<?xml version="1.0" ?>
<robot name="omni_robot" xmlns:xacro="http://www.ros.org/wiki/xacro">

<xacro:include filename="$(find omni_robot_description)/urdf/materials.xacro" />
<xacro:include filename="$(find omni_robot_description)/urdf/omni_robot.trans" />
<xacro:include filename="$(find omni_robot_description)/urdf/omni_robot.gazebo" />
<link name="base_link">
  <inertial>
    <origin xyz="-0.00039055834309408623 1.8970697824213494e-17 0.013449503145948333" rpy="0 0 0"/>
    <mass value="7.526906469202046"/>
    <inertia ixx="0.018693" iyy="0.018693" izz="0.035927" ixy="-0.0" iyz="-0.0" ixz="3e-06"/>
  </inertial>
  <visual>
    <origin xyz="0 0 0" rpy="0 0 0"/>
    <geometry>
      <mesh filename="file://$(find omni_robot_description)/meshes/base_link.stl" scale="0.001 0.001 0.001"/>
    </geometry>
    <material name="silver"/>
  </visual>
  <collision>
    <origin xyz="0 0 0" rpy="0 0 0"/>
    <geometry>
      <mesh filename="file://$(find omni_robot_description)/meshes/base_link.stl" scale="0.001 0.001 0.001"/>
    </geometry>
  </collision>
</link>

<link name="rim_1_1">
  <inertial>
    <origin xyz="0.00899995139183217 3.200222004718161e-14 -3.8621820508226434e-07" rpy="0 0 0"/>
    <mass value="0.14023608587607866"/>
    <inertia ixx="5e-05" iyy="3e-05" izz="3e-05" ixy="-0.0" iyz="-0.0" ixz="-0.0"/>
  </inertial>
  <visual>
    <origin xyz="0.130374 0.0 -0.012426" rpy="0 0 0"/>
    <geometry>
      <mesh filename="file://$(find omni_robot_description)/meshes/rim_1_1.stl" scale="0.001 0.001 0.001"/>
    </geometry>
    <material name="silver"/>
  </visual>
  <collision>
    <origin xyz="0.130374 0.0 -0.012426" rpy="0 0 0"/>
    <geometry>
      <mesh filename="file://$(find omni_robot_description)/meshes/rim_1_1.stl" scale="0.001 0.001 0.001"/>
    </geometry>
  </collision>
</link>

<link name="rim_2_1">
  <inertial>
    <origin xyz="-4.860822816189726e-08 0.008999999999999966 -3.8621817657555346e-07" rpy="0 0 0"/>
    <mass value="0.1402360858760785"/>
    <inertia ixx="3e-05" iyy="5e-05" izz="3e-05" ixy="0.0" iyz="-0.0" ixz="0.0"/>
  </inertial>
  <visual>
    <origin xyz="0.000374 0.13 -0.012426" rpy="0 0 0"/>
    <geometry>
      <mesh filename="file://$(find omni_robot_description)/meshes/rim_2_1.stl" scale="0.001 0.001 0.001"/>
    </geometry>
    <material name="silver"/>
  </visual>
  <collision>
    <origin xyz="0.000374 0.13 -0.012426" rpy="0 0 0"/>
    <geometry>
      <mesh filename="file://$(find omni_robot_description)/meshes/rim_2_1.stl" scale="0.001 0.001 0.001"/>
    </geometry>
  </collision>
</link>

<link name="rim_3_1">
  <inertial>
    <origin xyz="-0.009000048608167707 3.2057903750967407e-14 -3.8621820497818093e-07" rpy="0 0 0"/>
    <mass value="0.14023608587607866"/>
    <inertia ixx="5e-05" iyy="3e-05" izz="3e-05" ixy="-0.0" iyz="-0.0" ixz="0.0"/>
  </inertial>
  <visual>
    <origin xyz="-0.129626 0.0 -0.012426" rpy="0 0 0"/>
    <geometry>
      <mesh filename="file://$(find omni_robot_description)/meshes/rim_3_1.stl" scale="0.001 0.001 0.001"/>
    </geometry>
    <material name="silver"/>
  </visual>
  <collision>
    <origin xyz="-0.129626 0.0 -0.012426" rpy="0 0 0"/>
    <geometry>
      <mesh filename="file://$(find omni_robot_description)/meshes/rim_3_1.stl" scale="0.001 0.001 0.001"/>
    </geometry>
  </collision>
</link>

<link name="rim_4_1">
  <inertial>
    <origin xyz="-4.860822806258434e-08 -0.009000000000000077 -3.8621817657555346e-07" rpy="0 0 0"/>
    <mass value="0.14023608587607855"/>
    <inertia ixx="3e-05" iyy="5e-05" izz="3e-05" ixy="0.0" iyz="-0.0" ixz="0.0"/>
  </inertial>
  <visual>
    <origin xyz="0.000374 -0.13 -0.012426" rpy="0 0 0"/>
    <geometry>
      <mesh filename="file://$(find omni_robot_description)/meshes/rim_4_1.stl" scale="0.001 0.001 0.001"/>
    </geometry>
    <material name="silver"/>
  </visual>
  <collision>
    <origin xyz="0.000374 -0.13 -0.012426" rpy="0 0 0"/>
    <geometry>
      <mesh filename="file://$(find omni_robot_description)/meshes/rim_4_1.stl" scale="0.001 0.001 0.001"/>
    </geometry>
  </collision>
</link>

<link name="roller_1_2_1">
  <inertial>
    <origin xyz="-4.8608167907415734e-08 -0.007152434060027909 0.005157276950545811" rpy="0 0 0"/>
    <mass value="0.017098974596301414"/>
    <inertia ixx="1e-06" iyy="0.0" izz="1e-06" ixy="0.0" iyz="0.0" ixz="-0.0"/>
  </inertial>
  <visual>
    <origin xyz="0.128124 -0.020392 -0.024892" rpy="0 0 0"/>
    <geometry>
      <mesh filename="file://$(find omni_robot_description)/meshes/roller_1_2_1.stl" scale="0.001 0.001 0.001"/>
    </geometry>
    <material name="silver"/>
  </visual>
  <collision>
    <origin xyz="0.128124 -0.020392 -0.024892" rpy="0 0 0"/>
    <geometry>
      <mesh filename="file://$(find omni_robot_description)/meshes/roller_1_2_1.stl" scale="0.001 0.001 0.001"/>
    </geometry>
  </collision>
</link>

<link name="roller_1_1_1">
  <inertial>
    <origin xyz="-4.860816793517131e-08 0.002695350571172799 0.00839604974399046" rpy="0 0 0"/>
    <mass value="0.017098974596301386"/>
    <inertia ixx="1e-06" iyy="1e-06" izz="0.0" ixy="-0.0" iyz="-0.0" ixz="0.0"/>
  </inertial>
  <visual>
    <origin xyz="0.128124 -0.018157 0.003116" rpy="0 0 0"/>
    <geometry>
      <mesh filename="file://$(find omni_robot_description)/meshes/roller_1_1_1.stl" scale="0.001 0.001 0.001"/>
    </geometry>
    <material name="silver"/>
  </visual>
  <collision>
    <origin xyz="0.128124 -0.018157 0.003116" rpy="0 0 0"/>
    <geometry>
      <mesh filename="file://$(find omni_robot_description)/meshes/roller_1_1_1.stl" scale="0.001 0.001 0.001"/>
    </geometry>
  </collision>
</link>

<link name="roller_1_5_1">
  <inertial>
    <origin xyz="-4.860816793517131e-08 0.008817895458340549 3.174916897563142e-05" rpy="0 0 0"/>
    <mass value="0.017098974596301345"/>
    <inertia ixx="1e-06" iyy="0.0" izz="1e-06" ixy="0.0" iyz="-0.0" ixz="0.0"/>
  </inertial>
  <visual>
    <origin xyz="0.128124 0.00917 0.009646" rpy="0 0 0"/>
    <geometry>
      <mesh filename="file://$(find omni_robot_description)/meshes/roller_1_5_1.stl" scale="0.001 0.001 0.001"/>
    </geometry>
    <material name="silver"/>
  </visual>
  <collision>
    <origin xyz="0.128124 0.00917 0.009646" rpy="0 0 0"/>
    <geometry>
      <mesh filename="file://$(find omni_robot_description)/meshes/roller_1_5_1.stl" scale="0.001 0.001 0.001"/>
    </geometry>
  </collision>
</link>

<link name="roller_1_3_1">
  <inertial>
    <origin xyz="-4.860816787966016e-08 0.0027550368544883505 -0.008377207618485365" rpy="0 0 0"/>
    <mass value="0.01709897459630136"/>
    <inertia ixx="1e-06" iyy="1e-06" izz="0.0" ixy="-0.0" iyz="0.0" ixz="-0.0"/>
  </inertial>
  <visual>
    <origin xyz="0.128124 0.023825 -0.014327" rpy="0 0 0"/>
    <geometry>
      <mesh filename="file://$(find omni_robot_description)/meshes/roller_1_3_1.stl" scale="0.001 0.001 0.001"/>
    </geometry>
    <material name="silver"/>
  </visual>
  <collision>
    <origin xyz="0.128124 0.023825 -0.014327" rpy="0 0 0"/>
    <geometry>
      <mesh filename="file://$(find omni_robot_description)/meshes/roller_1_3_1.stl" scale="0.001 0.001 0.001"/>
    </geometry>
  </collision>
</link>

<link name="roller_1_4_1">
  <inertial>
    <origin xyz="-4.860816810170476e-08 -0.0071158488239748425 -0.005208799335749234" rpy="0 0 0"/>
    <mass value="0.017098974596301365"/>
    <inertia ixx="1e-06" iyy="0.0" izz="1e-06" ixy="0.0" iyz="-0.0" ixz="-0.0"/>
  </inertial>
  <visual>
    <origin xyz="0.128124 0.005554 -0.035672" rpy="0 0 0"/>
    <geometry>
      <mesh filename="file://$(find omni_robot_description)/meshes/roller_1_4_1.stl" scale="0.001 0.001 0.001"/>
    </geometry>
    <material name="silver"/>
  </visual>
  <collision>
    <origin xyz="0.128124 0.005554 -0.035672" rpy="0 0 0"/>
    <geometry>
      <mesh filename="file://$(find omni_robot_description)/meshes/roller_1_4_1.stl" scale="0.001 0.001 0.001"/>
    </geometry>
  </collision>
</link>

<link name="roller_1_9_1">
  <inertial>
    <origin xyz="-4.8608168018438036e-08 0.007097166613708081 0.005234847529153874" rpy="0 0 0"/>
    <mass value="0.017098974596301372"/>
    <inertia ixx="1e-06" iyy="0.0" izz="1e-06" ixy="-0.0" iyz="-0.0" ixz="0.0"/>
  </inertial>
  <visual>
    <origin xyz="0.114624 -0.005568 0.010811" rpy="0 0 0"/>
    <geometry>
      <mesh filename="file://$(find omni_robot_description)/meshes/roller_1_9_1.stl" scale="0.001 0.001 0.001"/>
    </geometry>
    <material name="silver"/>
  </visual>
  <collision>
    <origin xyz="0.114624 -0.005568 0.010811" rpy="0 0 0"/>
    <geometry>
      <mesh filename="file://$(find omni_robot_description)/meshes/roller_1_9_1.stl" scale="0.001 0.001 0.001"/>
    </geometry>
  </collision>
</link>

<link name="roller_1_7_1">
  <inertial>
    <origin xyz="-4.860816785190458e-08 0.007171054620771836 -0.005131527156925909" rpy="0 0 0"/>
    <mass value="0.017098974596301407"/>
    <inertia ixx="1e-06" iyy="0.0" izz="1e-06" ixy="0.0" iyz="0.0" ixz="-0.0"/>
  </inertial>
  <visual>
    <origin xyz="0.114624 0.020378 5.1e-05" rpy="0 0 0"/>
    <geometry>
      <mesh filename="file://$(find omni_robot_description)/meshes/roller_1_7_1.stl" scale="0.001 0.001 0.001"/>
    </geometry>
    <material name="silver"/>
  </visual>
  <collision>
    <origin xyz="0.114624 0.020378 5.1e-05" rpy="0 0 0"/>
    <geometry>
      <mesh filename="file://$(find omni_robot_description)/meshes/roller_1_7_1.stl" scale="0.001 0.001 0.001"/>
    </geometry>
  </collision>
</link>

<link name="roller_1_6_1">
  <inertial>
    <origin xyz="-4.86081679490491e-08 -0.0026645077456347727 -0.00840604954430816" rpy="0 0 0"/>
    <mass value="0.017098974596301393"/>
    <inertia ixx="1e-06" iyy="1e-06" izz="0.0" ixy="0.0" iyz="-0.0" ixz="-0.0"/>
  </inertial>
  <visual>
    <origin xyz="0.114624 0.018163 -0.027951" rpy="0 0 0"/>
    <geometry>
      <mesh filename="file://$(find omni_robot_description)/meshes/roller_1_6_1.stl" scale="0.001 0.001 0.001"/>
    </geometry>
    <material name="silver"/>
  </visual>
  <collision>
    <origin xyz="0.114624 0.018163 -0.027951" rpy="0 0 0"/>
    <geometry>
      <mesh filename="file://$(find omni_robot_description)/meshes/roller_1_6_1.stl" scale="0.001 0.001 0.001"/>
    </geometry>
  </collision>
</link>

<link name="roller_1_10_1">
  <inertial>
    <origin xyz="-4.860816775476007e-08 -0.008818162308526037 -6.325323757874063e-05" rpy="0 0 0"/>
    <mass value="0.017098974596301414"/>
    <inertia ixx="1e-06" iyy="0.0" izz="1e-06" ixy="0.0" iyz="-0.0" ixz="0.0"/>
  </inertial>
  <visual>
    <origin xyz="0.114624 -0.009153 -0.034497" rpy="0 0 0"/>
    <geometry>
      <mesh filename="file://$(find omni_robot_description)/meshes/roller_1_10_1.stl" scale="0.001 0.001 0.001"/>
    </geometry>
    <material name="silver"/>
  </visual>
  <collision>
    <origin xyz="0.114624 -0.009153 -0.034497" rpy="0 0 0"/>
    <geometry>
      <mesh filename="file://$(find omni_robot_description)/meshes/roller_1_10_1.stl" scale="0.001 0.001 0.001"/>
    </geometry>
  </collision>
</link>

<link name="roller_1_8_1">
  <inertial>
    <origin xyz="-4.860816819884928e-08 -0.0027855511803199853 0.00836705131893639" rpy="0 0 0"/>
    <mass value="0.017098974596301397"/>
    <inertia ixx="1e-06" iyy="1e-06" izz="0.0" ixy="-0.0" iyz="0.0" ixz="0.0"/>
  </inertial>
  <visual>
    <origin xyz="0.114624 -0.02382 -0.010541" rpy="0 0 0"/>
    <geometry>
      <mesh filename="file://$(find omni_robot_description)/meshes/roller_1_8_1.stl" scale="0.001 0.001 0.001"/>
    </geometry>
    <material name="silver"/>
  </visual>
  <collision>
    <origin xyz="0.114624 -0.02382 -0.010541" rpy="0 0 0"/>
    <geometry>
      <mesh filename="file://$(find omni_robot_description)/meshes/roller_1_8_1.stl" scale="0.001 0.001 0.001"/>
    </geometry>
  </collision>
</link>

<link name="roller_2_6_1">
  <inertial>
    <origin xyz="0.008396270399259482 -1.1102230246251565e-16 -0.0026944538718184155" rpy="0 0 0"/>
    <mass value="0.017098974596301355"/>
    <inertia ixx="0.0" iyy="1e-06" izz="1e-06" ixy="-0.0" iyz="0.0" ixz="0.0"/>
  </inertial>
  <visual>
    <origin xyz="0.002446 0.12775 -0.036236" rpy="0 0 0"/>
    <geometry>
      <mesh filename="file://$(find omni_robot_description)/meshes/roller_2_6_1.stl" scale="0.001 0.001 0.001"/>
    </geometry>
    <material name="silver"/>
  </visual>
  <collision>
    <origin xyz="0.002446 0.12775 -0.036236" rpy="0 0 0"/>
    <geometry>
      <mesh filename="file://$(find omni_robot_description)/meshes/roller_2_6_1.stl" scale="0.001 0.001 0.001"/>
    </geometry>
  </collision>
</link>

<link name="roller_2_7_1">
  <inertial>
    <origin xyz="0.0051578283873547 -4.163336342344337e-16 0.007152580532084868" rpy="0 0 0"/>
    <mass value="0.017098974596301372"/>
    <inertia ixx="1e-06" iyy="1e-06" izz="0.0" ixy="0.0" iyz="0.0" ixz="-0.0"/>
  </inertial>
  <visual>
    <origin xyz="0.02366 0.12775 -0.017813" rpy="0 0 0"/>
    <geometry>
      <mesh filename="file://$(find omni_robot_description)/meshes/roller_2_7_1.stl" scale="0.001 0.001 0.001"/>
    </geometry>
    <material name="silver"/>
  </visual>
  <collision>
    <origin xyz="0.02366 0.12775 -0.017813" rpy="0 0 0"/>
    <geometry>
      <mesh filename="file://$(find omni_robot_description)/meshes/roller_2_7_1.stl" scale="0.001 0.001 0.001"/>
    </geometry>
  </collision>
</link>

<link name="roller_2_9_1">
  <inertial>
    <origin xyz="-0.005209163784600828 0.0 0.007115807104964769" rpy="0 0 0"/>
    <mass value="0.01709897459630136"/>
    <inertia ixx="1e-06" iyy="1e-06" izz="0.0" ixy="-0.0" iyz="-0.0" ixz="0.0"/>
  </inertial>
  <visual>
    <origin xyz="0.012693 0.12775 0.008056" rpy="0 0 0"/>
    <geometry>
      <mesh filename="file://$(find omni_robot_description)/meshes/roller_2_9_1.stl" scale="0.001 0.001 0.001"/>
    </geometry>
    <material name="silver"/>
  </visual>
  <collision>
    <origin xyz="0.012693 0.12775 0.008056" rpy="0 0 0"/>
    <geometry>
      <mesh filename="file://$(find omni_robot_description)/meshes/roller_2_9_1.stl" scale="0.001 0.001 0.001"/>
    </geometry>
  </collision>
</link>

<link name="roller_2_8_1">
  <inertial>
    <origin xyz="-0.008376896541448615 -3.3306690738754696e-16 -0.002754875781752755" rpy="0 0 0"/>
    <mass value="0.01709897459630136"/>
    <inertia ixx="0.0" iyy="1e-06" izz="1e-06" ixy="-0.0" iyz="0.0" ixz="-0.0"/>
  </inertial>
  <visual>
    <origin xyz="-0.015298 0.12775 0.00562" rpy="0 0 0"/>
    <geometry>
      <mesh filename="file://$(find omni_robot_description)/meshes/roller_2_8_1.stl" scale="0.001 0.001 0.001"/>
    </geometry>
    <material name="silver"/>
  </visual>
  <collision>
    <origin xyz="-0.015298 0.12775 0.00562" rpy="0 0 0"/>
    <geometry>
      <mesh filename="file://$(find omni_robot_description)/meshes/roller_2_8_1.stl" scale="0.001 0.001 0.001"/>
    </geometry>
  </collision>
</link>

<link name="roller_2_10_1">
  <inertial>
    <origin xyz="3.171849859690684e-05 -1.3877787807814457e-16 -0.008817989074200946" rpy="0 0 0"/>
    <mass value="0.017098974596301376"/>
    <inertia ixx="1e-06" iyy="1e-06" izz="0.0" ixy="0.0" iyz="-0.0" ixz="0.0"/>
  </inertial>
  <visual>
    <origin xyz="-0.021631 0.12775 -0.021754" rpy="0 0 0"/>
    <geometry>
      <mesh filename="file://$(find omni_robot_description)/meshes/roller_2_10_1.stl" scale="0.001 0.001 0.001"/>
    </geometry>
    <material name="silver"/>
  </visual>
  <collision>
    <origin xyz="-0.021631 0.12775 -0.021754" rpy="0 0 0"/>
    <geometry>
      <mesh filename="file://$(find omni_robot_description)/meshes/roller_2_10_1.stl" scale="0.001 0.001 0.001"/>
    </geometry>
  </collision>
</link>

<link name="roller_2_1_1">
  <inertial>
    <origin xyz="-0.008387238663895057 0.0 0.0027251473247736253" rpy="0 0 0"/>
    <mass value="0.017098974596301365"/>
    <inertia ixx="0.0" iyy="1e-06" izz="1e-06" ixy="-0.0" iyz="-0.0" ixz="0.0"/>
  </inertial>
  <visual>
    <origin xyz="-0.001682 0.11425 0.01138" rpy="0 0 0"/>
    <geometry>
      <mesh filename="file://$(find omni_robot_description)/meshes/roller_2_1_1.stl" scale="0.001 0.001 0.001"/>
    </geometry>
    <material name="silver"/>
  </visual>
  <collision>
    <origin xyz="-0.001682 0.11425 0.01138" rpy="0 0 0"/>
    <geometry>
      <mesh filename="file://$(find omni_robot_description)/meshes/roller_2_1_1.stl" scale="0.001 0.001 0.001"/>
    </geometry>
  </collision>
</link>

<link name="roller_2_2_1">
  <inertial>
    <origin xyz="-0.005183778939455836 1.3877787807814457e-17 -0.007133928161136459" rpy="0 0 0"/>
    <mass value="0.01709897459630136"/>
    <inertia ixx="1e-06" iyy="1e-06" izz="0.0" ixy="0.0" iyz="-0.0" ixz="-0.0"/>
  </inertial>
  <visual>
    <origin xyz="-0.022902 0.11425 -0.007024" rpy="0 0 0"/>
    <geometry>
      <mesh filename="file://$(find omni_robot_description)/meshes/roller_2_2_1.stl" scale="0.001 0.001 0.001"/>
    </geometry>
    <material name="silver"/>
  </visual>
  <collision>
    <origin xyz="-0.022902 0.11425 -0.007024" rpy="0 0 0"/>
    <geometry>
      <mesh filename="file://$(find omni_robot_description)/meshes/roller_2_2_1.stl" scale="0.001 0.001 0.001"/>
    </geometry>
  </collision>
</link>

<link name="roller_2_4_1">
  <inertial>
    <origin xyz="0.005183779036452337 -4.163336342344337e-17 -0.007134310749231279" rpy="0 0 0"/>
    <mass value="0.017098974596301407"/>
    <inertia ixx="1e-06" iyy="1e-06" izz="0.0" ixy="0.0" iyz="0.0" ixz="0.0"/>
  </inertial>
  <visual>
    <origin xyz="-0.011955 0.11425 -0.032893" rpy="0 0 0"/>
    <geometry>
      <mesh filename="file://$(find omni_robot_description)/meshes/roller_2_4_1.stl" scale="0.001 0.001 0.001"/>
    </geometry>
    <material name="silver"/>
  </visual>
  <collision>
    <origin xyz="-0.011955 0.11425 -0.032893" rpy="0 0 0"/>
    <geometry>
      <mesh filename="file://$(find omni_robot_description)/meshes/roller_2_4_1.stl" scale="0.001 0.001 0.001"/>
    </geometry>
  </collision>
</link>

<link name="roller_2_3_1">
  <inertial>
    <origin xyz="0.008387204446614421 -1.249000902703301e-16 0.002725449539203142" rpy="0 0 0"/>
    <mass value="0.017098974596301355"/>
    <inertia ixx="0.0" iyy="1e-06" izz="1e-06" ixy="0.0" iyz="0.0" ixz="-0.0"/>
  </inertial>
  <visual>
    <origin xyz="0.01603 0.11425 -0.030476" rpy="0 0 0"/>
    <geometry>
      <mesh filename="file://$(find omni_robot_description)/meshes/roller_2_3_1.stl" scale="0.001 0.001 0.001"/>
    </geometry>
    <material name="silver"/>
  </visual>
  <collision>
    <origin xyz="0.01603 0.11425 -0.030476" rpy="0 0 0"/>
    <geometry>
      <mesh filename="file://$(find omni_robot_description)/meshes/roller_2_3_1.stl" scale="0.001 0.001 0.001"/>
    </geometry>
  </collision>
</link>

<link name="roller_2_5_1">
  <inertial>
    <origin xyz="-2.0892055430446477e-07 -1.8041124150158794e-16 0.008818710955668774" rpy="0 0 0"/>
    <mass value="0.017098974596301397"/>
    <inertia ixx="1e-06" iyy="1e-06" izz="0.0" ixy="-0.0" iyz="0.0" ixz="0.0"/>
  </inertial>
  <visual>
    <origin xyz="0.022379 0.11425 -0.003114" rpy="0 0 0"/>
    <geometry>
      <mesh filename="file://$(find omni_robot_description)/meshes/roller_2_5_1.stl" scale="0.001 0.001 0.001"/>
    </geometry>
    <material name="silver"/>
  </visual>
  <collision>
    <origin xyz="0.022379 0.11425 -0.003114" rpy="0 0 0"/>
    <geometry>
      <mesh filename="file://$(find omni_robot_description)/meshes/roller_2_5_1.stl" scale="0.001 0.001 0.001"/>
    </geometry>
  </collision>
</link>

<link name="roller_3_10_1">
  <inertial>
    <origin xyz="-4.860816768537113e-08 0.00881860285605633 3.1380888620168024e-05" rpy="0 0 0"/>
    <mass value="0.017098974596301414"/>
    <inertia ixx="1e-06" iyy="0.0" izz="1e-06" ixy="0.0" iyz="-0.0" ixz="-0.0"/>
  </inertial>
  <visual>
    <origin xyz="-0.127376 0.009329 -0.034431" rpy="0 0 0"/>
    <geometry>
      <mesh filename="file://$(find omni_robot_description)/meshes/roller_3_10_1.stl" scale="0.001 0.001 0.001"/>
    </geometry>
    <material name="silver"/>
  </visual>
  <collision>
    <origin xyz="-0.127376 0.009329 -0.034431" rpy="0 0 0"/>
    <geometry>
      <mesh filename="file://$(find omni_robot_description)/meshes/roller_3_10_1.stl" scale="0.001 0.001 0.001"/>
    </geometry>
  </collision>
</link>

<link name="roller_3_6_1">
  <inertial>
    <origin xyz="-4.8608167463326524e-08 0.0026950676536738327 0.008396932789282779" rpy="0 0 0"/>
    <mass value="0.01709897459630135"/>
    <inertia ixx="1e-06" iyy="1e-06" izz="0.0" ixy="-0.0" iyz="-0.0" ixz="-0.0"/>
  </inertial>
  <visual>
    <origin xyz="-0.127376 0.023811 -0.010353" rpy="0 0 0"/>
    <geometry>
      <mesh filename="file://$(find omni_robot_description)/meshes/roller_3_6_1.stl" scale="0.001 0.001 0.001"/>
    </geometry>
    <material name="silver"/>
  </visual>
  <collision>
    <origin xyz="-0.127376 0.023811 -0.010353" rpy="0 0 0"/>
    <geometry>
      <mesh filename="file://$(find omni_robot_description)/meshes/roller_3_6_1.stl" scale="0.001 0.001 0.001"/>
    </geometry>
  </collision>
</link>

<link name="roller_3_7_1">
  <inertial>
    <origin xyz="-4.8608167463326524e-08 -0.00715296675022955 0.005157490777378008" rpy="0 0 0"/>
    <mass value="0.017098974596301404"/>
    <inertia ixx="1e-06" iyy="0.0" izz="1e-06" ixy="0.0" iyz="0.0" ixz="-0.0"/>
  </inertial>
  <visual>
    <origin xyz="-0.127376 0.005387 0.01086" rpy="0 0 0"/>
    <geometry>
      <mesh filename="file://$(find omni_robot_description)/meshes/roller_3_7_1.stl" scale="0.001 0.001 0.001"/>
    </geometry>
    <material name="silver"/>
  </visual>
  <collision>
    <origin xyz="-0.127376 0.005387 0.01086" rpy="0 0 0"/>
    <geometry>
      <mesh filename="file://$(find omni_robot_description)/meshes/roller_3_7_1.stl" scale="0.001 0.001 0.001"/>
    </geometry>
  </collision>
</link>

<link name="roller_3_9_1">
  <inertial>
    <origin xyz="-4.860816735230422e-08 -0.007115193323109333 -0.005208501394577663" rpy="0 0 0"/>
    <mass value="0.01709897459630137"/>
    <inertia ixx="1e-06" iyy="0.0" izz="1e-06" ixy="0.0" iyz="-0.0" ixz="-0.0"/>
  </inertial>
  <visual>
    <origin xyz="-0.127376 -0.020481 -0.000106" rpy="0 0 0"/>
    <geometry>
      <mesh filename="file://$(find omni_robot_description)/meshes/roller_3_9_1.stl" scale="0.001 0.001 0.001"/>
    </geometry>
    <material name="silver"/>
  </visual>
  <collision>
    <origin xyz="-0.127376 -0.020481 -0.000106" rpy="0 0 0"/>
    <geometry>
      <mesh filename="file://$(find omni_robot_description)/meshes/roller_3_9_1.stl" scale="0.001 0.001 0.001"/>
    </geometry>
  </collision>
</link>

<link name="roller_3_8_1">
  <inertial>
    <origin xyz="-4.860816718577077e-08 0.002755489563608139 -0.008377234151425432" rpy="0 0 0"/>
    <mass value="0.017098974596301397"/>
    <inertia ixx="1e-06" iyy="1e-06" izz="0.0" ixy="0.0" iyz="0.0" ixz="-0.0"/>
  </inertial>
  <visual>
    <origin xyz="-0.127376 -0.018045 -0.028098" rpy="0 0 0"/>
    <geometry>
      <mesh filename="file://$(find omni_robot_description)/meshes/roller_3_8_1.stl" scale="0.001 0.001 0.001"/>
    </geometry>
    <material name="silver"/>
  </visual>
  <collision>
    <origin xyz="-0.127376 -0.018045 -0.028098" rpy="0 0 0"/>
    <geometry>
      <mesh filename="file://$(find omni_robot_description)/meshes/roller_3_8_1.stl" scale="0.001 0.001 0.001"/>
    </geometry>
  </collision>
</link>

<link name="roller_3_5_1">
  <inertial>
    <origin xyz="-4.86081674910821e-08 -0.008818097173813473 4.534694689351665e-07" rpy="0 0 0"/>
    <mass value="0.017098974596301345"/>
    <inertia ixx="1e-06" iyy="0.0" izz="1e-06" ixy="0.0" iyz="-0.0" ixz="-0.0"/>
  </inertial>
  <visual>
    <origin xyz="-0.113876 -0.009311 0.00958" rpy="0 0 0"/>
    <geometry>
      <mesh filename="file://$(find omni_robot_description)/meshes/roller_3_5_1.stl" scale="0.001 0.001 0.001"/>
    </geometry>
    <material name="silver"/>
  </visual>
  <collision>
    <origin xyz="-0.113876 -0.009311 0.00958" rpy="0 0 0"/>
    <geometry>
      <mesh filename="file://$(find omni_robot_description)/meshes/roller_3_5_1.stl" scale="0.001 0.001 0.001"/>
    </geometry>
  </collision>
</link>

<link name="roller_3_1_1">
  <inertial>
    <origin xyz="-4.8608167463326524e-08 -0.002725533542918164 -0.008386576273871856" rpy="0 0 0"/>
    <mass value="0.017098974596301355"/>
    <inertia ixx="1e-06" iyy="1e-06" izz="0.0" ixy="0.0" iyz="-0.0" ixz="-0.0"/>
  </inertial>
  <visual>
    <origin xyz="-0.113876 -0.023806 -0.014481" rpy="0 0 0"/>
    <geometry>
      <mesh filename="file://$(find omni_robot_description)/meshes/roller_3_1_1.stl" scale="0.001 0.001 0.001"/>
    </geometry>
    <material name="silver"/>
  </visual>
  <collision>
    <origin xyz="-0.113876 -0.023806 -0.014481" rpy="0 0 0"/>
    <geometry>
      <mesh filename="file://$(find omni_robot_description)/meshes/roller_3_1_1.stl" scale="0.001 0.001 0.001"/>
    </geometry>
  </collision>
</link>

<link name="roller_3_2_1">
  <inertial>
    <origin xyz="-4.8608167713126704e-08 0.007134541942991779 -0.005183116549432602" rpy="0 0 0"/>
    <mass value="0.017098974596301428"/>
    <inertia ixx="1e-06" iyy="0.0" izz="1e-06" ixy="-0.0" iyz="0.0" ixz="-0.0"/>
  </inertial>
  <visual>
    <origin xyz="-0.113876 -0.005401 -0.035701" rpy="0 0 0"/>
    <geometry>
      <mesh filename="file://$(find omni_robot_description)/meshes/roller_3_2_1.stl" scale="0.001 0.001 0.001"/>
    </geometry>
    <material name="silver"/>
  </visual>
  <collision>
    <origin xyz="-0.113876 -0.005401 -0.035701" rpy="0 0 0"/>
    <geometry>
      <mesh filename="file://$(find omni_robot_description)/meshes/roller_3_2_1.stl" scale="0.001 0.001 0.001"/>
    </geometry>
  </collision>
</link>

<link name="roller_3_4_1">
  <inertial>
    <origin xyz="-4.860816735230422e-08 0.007133924531086751 0.005183441426475626" rpy="0 0 0"/>
    <mass value="0.01709897459630134"/>
    <inertia ixx="1e-06" iyy="0.0" izz="1e-06" ixy="-0.0" iyz="-0.0" ixz="-0.0"/>
  </inertial>
  <visual>
    <origin xyz="-0.113876 0.020467 -0.024755" rpy="0 0 0"/>
    <geometry>
      <mesh filename="file://$(find omni_robot_description)/meshes/roller_3_4_1.stl" scale="0.001 0.001 0.001"/>
    </geometry>
    <material name="silver"/>
  </visual>
  <collision>
    <origin xyz="-0.113876 0.020467 -0.024755" rpy="0 0 0"/>
    <geometry>
      <mesh filename="file://$(find omni_robot_description)/meshes/roller_3_4_1.stl" scale="0.001 0.001 0.001"/>
    </geometry>
  </collision>
</link>

<link name="roller_3_3_1">
  <inertial>
    <origin xyz="-4.860816761598219e-08 -0.0027248357573476795 0.008386866836637741" rpy="0 0 0"/>
    <mass value="0.017098974596301345"/>
    <inertia ixx="1e-06" iyy="1e-06" izz="0.0" ixy="0.0" iyz="0.0" ixz="0.0"/>
  </inertial>
  <visual>
    <origin xyz="-0.113876 0.018051 0.00323" rpy="0 0 0"/>
    <geometry>
      <mesh filename="file://$(find omni_robot_description)/meshes/roller_3_3_1.stl" scale="0.001 0.001 0.001"/>
    </geometry>
    <material name="silver"/>
  </visual>
  <collision>
    <origin xyz="-0.113876 0.018051 0.00323" rpy="0 0 0"/>
    <geometry>
      <mesh filename="file://$(find omni_robot_description)/meshes/roller_3_3_1.stl" scale="0.001 0.001 0.001"/>
    </geometry>
  </collision>
</link>

<link name="roller_4_3_1">
  <inertial>
    <origin xyz="-0.008376870008508713 2.7755575615628914e-17 -0.002755423072633059" rpy="0 0 0"/>
    <mass value="0.017098974596301338"/>
    <inertia ixx="0.0" iyy="1e-06" izz="1e-06" ixy="-0.0" iyz="0.0" ixz="-0.0"/>
  </inertial>
  <visual>
    <origin xyz="-0.001527 -0.12775 -0.036251" rpy="0 0 0"/>
    <geometry>
      <mesh filename="file://$(find omni_robot_description)/meshes/roller_4_3_1.stl" scale="0.001 0.001 0.001"/>
    </geometry>
    <material name="silver"/>
  </visual>
  <collision>
    <origin xyz="-0.001527 -0.12775 -0.036251" rpy="0 0 0"/>
    <geometry>
      <mesh filename="file://$(find omni_robot_description)/meshes/roller_4_3_1.stl" scale="0.001 0.001 0.001"/>
    </geometry>
  </collision>
</link>

<link name="roller_4_4_1">
  <inertial>
    <origin xyz="-0.0052084617257725264 -8.326672684688674e-17 0.0071154626058303645" rpy="0 0 0"/>
    <mass value="0.017098974596301348"/>
    <inertia ixx="1e-06" iyy="1e-06" izz="0.0" ixy="-0.0" iyz="0.0" ixz="0.0"/>
  </inertial>
  <visual>
    <origin xyz="-0.022872 -0.12775 -0.01798" rpy="0 0 0"/>
    <geometry>
      <mesh filename="file://$(find omni_robot_description)/meshes/roller_4_4_1.stl" scale="0.001 0.001 0.001"/>
    </geometry>
    <material name="silver"/>
  </visual>
  <collision>
    <origin xyz="-0.022872 -0.12775 -0.01798" rpy="0 0 0"/>
    <geometry>
      <mesh filename="file://$(find omni_robot_description)/meshes/roller_4_4_1.stl" scale="0.001 0.001 0.001"/>
    </geometry>
  </collision>
</link>

<link name="roller_4_2_1">
  <inertial>
    <origin xyz="0.005157614560522916 -1.1102230246251565e-16 0.007153047841883474" rpy="0 0 0"/>
    <mass value="0.017098974596301365"/>
    <inertia ixx="1e-06" iyy="1e-06" izz="0.0" ixy="-0.0" iyz="0.0" ixz="-0.0"/>
  </inertial>
  <visual>
    <origin xyz="-0.012092 -0.12775 0.007967" rpy="0 0 0"/>
    <geometry>
      <mesh filename="file://$(find omni_robot_description)/meshes/roller_4_2_1.stl" scale="0.001 0.001 0.001"/>
    </geometry>
    <material name="silver"/>
  </visual>
  <collision>
    <origin xyz="-0.012092 -0.12775 0.007967" rpy="0 0 0"/>
    <geometry>
      <mesh filename="file://$(find omni_robot_description)/meshes/roller_4_2_1.stl" scale="0.001 0.001 0.001"/>
    </geometry>
  </collision>
</link>

<link name="roller_4_1_1">
  <inertial>
    <origin xyz="0.008396387353967742 -1.1102230246251565e-16 -0.002694736789317579" rpy="0 0 0"/>
    <mass value="0.01709897459630136"/>
    <inertia ixx="0.0" iyy="1e-06" izz="1e-06" ixy="0.0" iyz="0.0" ixz="0.0"/>
  </inertial>
  <visual>
    <origin xyz="0.015916 -0.12775 0.005732" rpy="0 0 0"/>
    <geometry>
      <mesh filename="file://$(find omni_robot_description)/meshes/roller_4_1_1.stl" scale="0.001 0.001 0.001"/>
    </geometry>
    <material name="silver"/>
  </visual>
  <collision>
    <origin xyz="0.015916 -0.12775 0.005732" rpy="0 0 0"/>
    <geometry>
      <mesh filename="file://$(find omni_robot_description)/meshes/roller_4_1_1.stl" scale="0.001 0.001 0.001"/>
    </geometry>
  </collision>
</link>

<link name="roller_4_5_1">
  <inertial>
    <origin xyz="3.208677895260442e-05 -2.7755575615628914e-17 -0.008818281676485537" rpy="0 0 0"/>
    <mass value="0.01709897459630139"/>
    <inertia ixx="1e-06" iyy="1e-06" izz="0.0" ixy="-0.0" iyz="0.0" ixz="0.0"/>
  </inertial>
  <visual>
    <origin xyz="0.022446 -0.12775 -0.021596" rpy="0 0 0"/>
    <geometry>
      <mesh filename="file://$(find omni_robot_description)/meshes/roller_4_5_1.stl" scale="0.001 0.001 0.001"/>
    </geometry>
    <material name="silver"/>
  </visual>
  <collision>
    <origin xyz="0.022446 -0.12775 -0.021596" rpy="0 0 0"/>
    <geometry>
      <mesh filename="file://$(find omni_robot_description)/meshes/roller_4_5_1.stl" scale="0.001 0.001 0.001"/>
    </geometry>
  </collision>
</link>

<link name="roller_4_6_1">
  <inertial>
    <origin xyz="-0.008405711934331494 -1.249000902703301e-16 0.0026651215274901517" rpy="0 0 0"/>
    <mass value="0.01709897459630136"/>
    <inertia ixx="0.0" iyy="1e-06" izz="1e-06" ixy="-0.0" iyz="-0.0" ixz="0.0"/>
  </inertial>
  <visual>
    <origin xyz="-0.015151 -0.11425 -0.030588" rpy="0 0 0"/>
    <geometry>
      <mesh filename="file://$(find omni_robot_description)/meshes/roller_4_6_1.stl" scale="0.001 0.001 0.001"/>
    </geometry>
    <material name="silver"/>
  </visual>
  <collision>
    <origin xyz="-0.015151 -0.11425 -0.030588" rpy="0 0 0"/>
    <geometry>
      <mesh filename="file://$(find omni_robot_description)/meshes/roller_4_6_1.stl" scale="0.001 0.001 0.001"/>
    </geometry>
  </collision>
</link>

<link name="roller_4_10_1">
  <inertial>
    <origin xyz="-6.291562760180058e-05 -2.7755575615628914e-17 0.008817776090381637" rpy="0 0 0"/>
    <mass value="0.017098974596301393"/>
    <inertia ixx="1e-06" iyy="1e-06" izz="0.0" ixy="0.0" iyz="0.0" ixz="0.0"/>
  </inertial>
  <visual>
    <origin xyz="-0.021697 -0.11425 -0.003273" rpy="0 0 0"/>
    <geometry>
      <mesh filename="file://$(find omni_robot_description)/meshes/roller_4_10_1.stl" scale="0.001 0.001 0.001"/>
    </geometry>
    <material name="silver"/>
  </visual>
  <collision>
    <origin xyz="-0.021697 -0.11425 -0.003273" rpy="0 0 0"/>
    <geometry>
      <mesh filename="file://$(find omni_robot_description)/meshes/roller_4_10_1.stl" scale="0.001 0.001 0.001"/>
    </geometry>
  </collision>
</link>

<link name="roller_4_8_1">
  <inertial>
    <origin xyz="0.008367388928913566 9.71445146547012e-17 0.0027851649621753946" rpy="0 0 0"/>
    <mass value="0.017098974596301362"/>
    <inertia ixx="0.0" iyy="1e-06" izz="1e-06" ixy="0.0" iyz="-0.0" ixz="-0.0"/>
  </inertial>
  <visual>
    <origin xyz="0.002259 -0.11425 0.011394" rpy="0 0 0"/>
    <geometry>
      <mesh filename="file://$(find omni_robot_description)/meshes/roller_4_8_1.stl" scale="0.001 0.001 0.001"/>
    </geometry>
    <material name="silver"/>
  </visual>
  <collision>
    <origin xyz="0.002259 -0.11425 0.011394" rpy="0 0 0"/>
    <geometry>
      <mesh filename="file://$(find omni_robot_description)/meshes/roller_4_8_1.stl" scale="0.001 0.001 0.001"/>
    </geometry>
  </collision>
</link>

<link name="roller_4_9_1">
  <inertial>
    <origin xyz="0.0052341851391310215 -9.71445146547012e-17 -0.007096552831852921" rpy="0 0 0"/>
    <mass value="0.017098974596301397"/>
    <inertia ixx="1e-06" iyy="1e-06" izz="0.0" ixy="0.0" iyz="0.0" ixz="0.0"/>
  </inertial>
  <visual>
    <origin xyz="0.02361 -0.11425 -0.006857" rpy="0 0 0"/>
    <geometry>
      <mesh filename="file://$(find omni_robot_description)/meshes/roller_4_9_1.stl" scale="0.001 0.001 0.001"/>
    </geometry>
    <material name="silver"/>
  </visual>
  <collision>
    <origin xyz="0.02361 -0.11425 -0.006857" rpy="0 0 0"/>
    <geometry>
      <mesh filename="file://$(find omni_robot_description)/meshes/roller_4_9_1.stl" scale="0.001 0.001 0.001"/>
    </geometry>
  </collision>
</link>

<link name="roller_4_7_1">
  <inertial>
    <origin xyz="-0.005132189546949051 -9.71445146547012e-17 -0.007171440838916722" rpy="0 0 0"/>
    <mass value="0.0170989745963014"/>
    <inertia ixx="1e-06" iyy="1e-06" izz="0.0" ixy="0.0" iyz="0.0" ixz="-0.0"/>
  </inertial>
  <visual>
    <origin xyz="0.01285 -0.11425 -0.032804" rpy="0 0 0"/>
    <geometry>
      <mesh filename="file://$(find omni_robot_description)/meshes/roller_4_7_1.stl" scale="0.001 0.001 0.001"/>
    </geometry>
    <material name="silver"/>
  </visual>
  <collision>
    <origin xyz="0.01285 -0.11425 -0.032804" rpy="0 0 0"/>
    <geometry>
      <mesh filename="file://$(find omni_robot_description)/meshes/roller_4_7_1.stl" scale="0.001 0.001 0.001"/>
    </geometry>
  </collision>
</link>

<link name="lidar_link_1">
  <inertial>
    <origin xyz="-1.618646594692824e-07 7.154338888081818e-16 0.007499613781855534" rpy="0 0 0"/>
    <mass value="0.5363876756922872"/>
    <inertia ixx="0.000204" iyy="0.000204" izz="0.000389" ixy="-0.0" iyz="-0.0" ixz="0.0"/>
  </inertial>
  <visual>
    <origin xyz="0.000777 0.0 -0.047426" rpy="0 0 0"/>
    <geometry>
      <mesh filename="file://$(find omni_robot_description)/meshes/lidar_link_1.stl" scale="0.001 0.001 0.001"/>
    </geometry>
    <material name="silver"/>
  </visual>
  <collision>
    <origin xyz="0.000777 0.0 -0.047426" rpy="0 0 0"/>
    <geometry>
      <mesh filename="file://$(find omni_robot_description)/meshes/lidar_link_1.stl" scale="0.001 0.001 0.001"/>
    </geometry>
  </collision>
</link>

<link name="imu_link_1">
  <inertial>
    <origin xyz="-0.005303349467066731 0.00530330085889906 -3.8621814528981557e-07" rpy="0 0 0"/>
    <mass value="0.02633495842824316"/>
    <inertia ixx="1e-06" iyy="1e-06" izz="1e-06" ixy="-0.0" iyz="0.0" ixz="0.0"/>
  </inertial>
  <visual>
    <origin xyz="0.065374 -0.065 -0.012426" rpy="0 0 0"/>
    <geometry>
      <mesh filename="file://$(find omni_robot_description)/meshes/imu_link_1.stl" scale="0.001 0.001 0.001"/>
    </geometry>
    <material name="silver"/>
  </visual>
  <collision>
    <origin xyz="0.065374 -0.065 -0.012426" rpy="0 0 0"/>
    <geometry>
      <mesh filename="file://$(find omni_robot_description)/meshes/imu_link_1.stl" scale="0.001 0.001 0.001"/>
    </geometry>
  </collision>
</link>

<joint name="Revolute 1" type="continuous">
  <origin xyz="-0.130374 0.0 0.012426" rpy="0 0 0"/>
  <parent link="base_link"/>
  <child link="rim_1_1"/>
  <axis xyz="-1.0 -0.0 -0.0"/>
</joint>

<joint name="Revolute 2" type="continuous">
  <origin xyz="-0.000374 -0.13 0.012426" rpy="0 0 0"/>
  <parent link="base_link"/>
  <child link="rim_2_1"/>
  <axis xyz="0.0 -1.0 0.0"/>
</joint>

<joint name="Revolute 3" type="continuous">
  <origin xyz="0.129626 0.0 0.012426" rpy="0 0 0"/>
  <parent link="base_link"/>
  <child link="rim_3_1"/>
  <axis xyz="1.0 0.0 0.0"/>
</joint>

<joint name="Revolute 4" type="continuous">
  <origin xyz="-0.000374 0.13 0.012426" rpy="0 0 0"/>
  <parent link="base_link"/>
  <child link="rim_4_1"/>
  <axis xyz="-0.0 1.0 0.0"/>
</joint>

<joint name="Revolute 5" type="continuous">
  <origin xyz="0.00225 0.020392 0.012466" rpy="0 0 0"/>
  <parent link="rim_1_1"/>
  <child link="roller_1_2_1"/>
  <axis xyz="0.0 0.811123 -0.584876"/>
</joint>

<joint name="Revolute 6" type="continuous">
  <origin xyz="0.00225 0.018157 -0.015542" rpy="0 0 0"/>
  <parent link="rim_1_1"/>
  <child link="roller_1_1_1"/>
  <axis xyz="0.0 -0.305599 -0.95216"/>
</joint>

<joint name="Revolute 7" type="continuous">
  <origin xyz="0.00225 -0.00917 -0.022072" rpy="0 0 0"/>
  <parent link="rim_1_1"/>
  <child link="roller_1_5_1"/>
  <axis xyz="-0.0 -0.999994 -0.003591"/>
</joint>

<joint name="Revolute 8" type="continuous">
  <origin xyz="0.00225 -0.023825 0.001901" rpy="0 0 0"/>
  <parent link="rim_1_1"/>
  <child link="roller_1_3_1"/>
  <axis xyz="-0.0 -0.312431 0.949941"/>
</joint>

<joint name="Revolute 9" type="continuous">
  <origin xyz="0.00225 -0.005554 0.023246" rpy="0 0 0"/>
  <parent link="rim_1_1"/>
  <child link="roller_1_4_1"/>
  <axis xyz="0.0 0.806901 0.590687"/>
</joint>

<joint name="Revolute 10" type="continuous">
  <origin xyz="0.01575 0.005568 -0.023237" rpy="0 0 0"/>
  <parent link="rim_1_1"/>
  <child link="roller_1_9_1"/>
  <axis xyz="-0.0 -0.804774 -0.593581"/>
</joint>

<joint name="Revolute 11" type="continuous">
  <origin xyz="0.01575 -0.020378 -0.012477" rpy="0 0 0"/>
  <parent link="rim_1_1"/>
  <child link="roller_1_7_1"/>
  <axis xyz="-0.0 -0.813218 0.581959"/>
</joint>

<joint name="Revolute 12" type="continuous">
  <origin xyz="0.01575 -0.018163 0.015525" rpy="0 0 0"/>
  <parent link="rim_1_1"/>
  <child link="roller_1_6_1"/>
  <axis xyz="-0.0 0.302178 0.953252"/>
</joint>

<joint name="Revolute 13" type="continuous">
  <origin xyz="0.01575 0.009153 0.022071" rpy="0 0 0"/>
  <parent link="rim_1_1"/>
  <child link="roller_1_10_1"/>
  <axis xyz="0.0 0.999974 0.007183"/>
</joint>

<joint name="Revolute 14" type="continuous">
  <origin xyz="0.01575 0.02382 -0.001885" rpy="0 0 0"/>
  <parent link="rim_1_1"/>
  <child link="roller_1_8_1"/>
  <axis xyz="0.0 0.31584 -0.948812"/>
</joint>

<joint name="Revolute 15" type="continuous">
  <origin xyz="-0.002072 0.00225 0.02381" rpy="0 0 0"/>
  <parent link="rim_2_1"/>
  <child link="roller_2_6_1"/>
  <axis xyz="-0.95216 -0.0 0.305599"/>
</joint>

<joint name="Revolute 16" type="continuous">
  <origin xyz="-0.023286 0.00225 0.005387" rpy="0 0 0"/>
  <parent link="rim_2_1"/>
  <child link="roller_2_7_1"/>
  <axis xyz="-0.584876 -0.0 -0.811123"/>
</joint>

<joint name="Revolute 17" type="continuous">
  <origin xyz="-0.012319 0.00225 -0.020482" rpy="0 0 0"/>
  <parent link="rim_2_1"/>
  <child link="roller_2_9_1"/>
  <axis xyz="0.590687 0.0 -0.806901"/>
</joint>

<joint name="Revolute 18" type="continuous">
  <origin xyz="0.015672 0.00225 -0.018046" rpy="0 0 0"/>
  <parent link="rim_2_1"/>
  <child link="roller_2_8_1"/>
  <axis xyz="0.949941 0.0 0.312431"/>
</joint>

<joint name="Revolute 19" type="continuous">
  <origin xyz="0.022005 0.00225 0.009328" rpy="0 0 0"/>
  <parent link="rim_2_1"/>
  <child link="roller_2_10_1"/>
  <axis xyz="-0.003591 -0.0 0.999994"/>
</joint>

<joint name="Revolute 20" type="continuous">
  <origin xyz="0.002056 0.01575 -0.023806" rpy="0 0 0"/>
  <parent link="rim_2_1"/>
  <child link="roller_2_1_1"/>
  <axis xyz="0.951057 0.0 -0.309017"/>
</joint>

<joint name="Revolute 21" type="continuous">
  <origin xyz="0.023276 0.01575 -0.005402" rpy="0 0 0"/>
  <parent link="rim_2_1"/>
  <child link="roller_2_2_1"/>
  <axis xyz="0.587785 0.0 0.809017"/>
</joint>

<joint name="Revolute 22" type="continuous">
  <origin xyz="0.012329 0.01575 0.020467" rpy="0 0 0"/>
  <parent link="rim_2_1"/>
  <child link="roller_2_4_1"/>
  <axis xyz="-0.587785 -0.0 0.809017"/>
</joint>

<joint name="Revolute 23" type="continuous">
  <origin xyz="-0.015656 0.01575 0.01805" rpy="0 0 0"/>
  <parent link="rim_2_1"/>
  <child link="roller_2_3_1"/>
  <axis xyz="-0.951057 -0.0 -0.309017"/>
</joint>

<joint name="Revolute 24" type="continuous">
  <origin xyz="-0.022005 0.01575 -0.009312" rpy="0 0 0"/>
  <parent link="rim_2_1"/>
  <child link="roller_2_5_1"/>
  <axis xyz="0.0 0.0 -1.0"/>
</joint>

<joint name="Revolute 25" type="continuous">
  <origin xyz="-0.00225 -0.009329 0.022005" rpy="0 0 0"/>
  <parent link="rim_3_1"/>
  <child link="roller_3_10_1"/>
  <axis xyz="-0.0 -0.999994 -0.003591"/>
</joint>

<joint name="Revolute 26" type="continuous">
  <origin xyz="-0.00225 -0.023811 -0.002073" rpy="0 0 0"/>
  <parent link="rim_3_1"/>
  <child link="roller_3_6_1"/>
  <axis xyz="0.0 -0.305599 -0.95216"/>
</joint>

<joint name="Revolute 27" type="continuous">
  <origin xyz="-0.00225 -0.005387 -0.023286" rpy="0 0 0"/>
  <parent link="rim_3_1"/>
  <child link="roller_3_7_1"/>
  <axis xyz="0.0 0.811123 -0.584876"/>
</joint>

<joint name="Revolute 28" type="continuous">
  <origin xyz="-0.00225 0.020481 -0.01232" rpy="0 0 0"/>
  <parent link="rim_3_1"/>
  <child link="roller_3_9_1"/>
  <axis xyz="0.0 0.806901 0.590687"/>
</joint>

<joint name="Revolute 29" type="continuous">
  <origin xyz="-0.00225 0.018045 0.015672" rpy="0 0 0"/>
  <parent link="rim_3_1"/>
  <child link="roller_3_8_1"/>
  <axis xyz="-0.0 -0.312431 0.949941"/>
</joint>

<joint name="Revolute 30" type="continuous">
  <origin xyz="-0.01575 0.009311 -0.022006" rpy="0 0 0"/>
  <parent link="rim_3_1"/>
  <child link="roller_3_5_1"/>
  <axis xyz="0.0 1.0 0.0"/>
</joint>

<joint name="Revolute 31" type="continuous">
  <origin xyz="-0.01575 0.023806 0.002055" rpy="0 0 0"/>
  <parent link="rim_3_1"/>
  <child link="roller_3_1_1"/>
  <axis xyz="-0.0 0.309017 0.951057"/>
</joint>

<joint name="Revolute 32" type="continuous">
  <origin xyz="-0.01575 0.005401 0.023275" rpy="0 0 0"/>
  <parent link="rim_3_1"/>
  <child link="roller_3_2_1"/>
  <axis xyz="-0.0 -0.809017 0.587785"/>
</joint>

<joint name="Revolute 33" type="continuous">
  <origin xyz="-0.01575 -0.020467 0.012329" rpy="0 0 0"/>
  <parent link="rim_3_1"/>
  <child link="roller_3_4_1"/>
  <axis xyz="-0.0 -0.809017 -0.587785"/>
</joint>

<joint name="Revolute 34" type="continuous">
  <origin xyz="-0.01575 -0.018051 -0.015656" rpy="0 0 0"/>
  <parent link="rim_3_1"/>
  <child link="roller_3_3_1"/>
  <axis xyz="0.0 0.309017 -0.951057"/>
</joint>

<joint name="Revolute 35" type="continuous">
  <origin xyz="0.001901 -0.00225 0.023825" rpy="0 0 0"/>
  <parent link="rim_4_1"/>
  <child link="roller_4_3_1"/>
  <axis xyz="0.949941 0.0 0.312431"/>
</joint>

<joint name="Revolute 36" type="continuous">
  <origin xyz="0.023246 -0.00225 0.005554" rpy="0 0 0"/>
  <parent link="rim_4_1"/>
  <child link="roller_4_4_1"/>
  <axis xyz="0.590687 0.0 -0.806901"/>
</joint>

<joint name="Revolute 37" type="continuous">
  <origin xyz="0.012466 -0.00225 -0.020393" rpy="0 0 0"/>
  <parent link="rim_4_1"/>
  <child link="roller_4_2_1"/>
  <axis xyz="-0.584876 -0.0 -0.811123"/>
</joint>

<joint name="Revolute 38" type="continuous">
  <origin xyz="-0.015542 -0.00225 -0.018158" rpy="0 0 0"/>
  <parent link="rim_4_1"/>
  <child link="roller_4_1_1"/>
  <axis xyz="-0.95216 -0.0 0.305599"/>
</joint>

<joint name="Revolute 39" type="continuous">
  <origin xyz="-0.022072 -0.00225 0.00917" rpy="0 0 0"/>
  <parent link="rim_4_1"/>
  <child link="roller_4_5_1"/>
  <axis xyz="-0.003591 -0.0 0.999994"/>
</joint>

<joint name="Revolute 40" type="continuous">
  <origin xyz="0.015525 -0.01575 0.018162" rpy="0 0 0"/>
  <parent link="rim_4_1"/>
  <child link="roller_4_6_1"/>
  <axis xyz="0.953252 0.0 -0.302178"/>
</joint>

<joint name="Revolute 41" type="continuous">
  <origin xyz="0.022071 -0.01575 -0.009153" rpy="0 0 0"/>
  <parent link="rim_4_1"/>
  <child link="roller_4_10_1"/>
  <axis xyz="0.007183 0.0 -0.999974"/>
</joint>

<joint name="Revolute 42" type="continuous">
  <origin xyz="-0.001885 -0.01575 -0.02382" rpy="0 0 0"/>
  <parent link="rim_4_1"/>
  <child link="roller_4_8_1"/>
  <axis xyz="-0.948812 -0.0 -0.31584"/>
</joint>

<joint name="Revolute 43" type="continuous">
  <origin xyz="-0.023236 -0.01575 -0.005569" rpy="0 0 0"/>
  <parent link="rim_4_1"/>
  <child link="roller_4_9_1"/>
  <axis xyz="-0.593581 -0.0 0.804774"/>
</joint>

<joint name="Revolute 44" type="continuous">
  <origin xyz="-0.012476 -0.01575 0.020378" rpy="0 0 0"/>
  <parent link="rim_4_1"/>
  <child link="roller_4_7_1"/>
  <axis xyz="0.581959 0.0 0.813218"/>
</joint>

<joint name="Rigid 45" type="fixed">
  <origin xyz="-0.000777 0.0 0.047426" rpy="0 0 0"/>
  <parent link="base_link"/>
  <child link="lidar_link_1"/>
</joint>

<joint name="Rigid 46" type="fixed">
  <origin xyz="-0.065374 0.065 0.012426" rpy="0 0 0"/>
  <parent link="base_link"/>
  <child link="imu_link_1"/>
</joint>

</robot>
