<?xml version="1.0" ?>
<robot name="omni_robot" xmlns:xacro="http://www.ros.org/wiki/xacro">

<xacro:include filename="$(find omni_robot_description)/urdf/materials.xacro" />
<xacro:include filename="$(find omni_robot_description)/urdf/omni_robot.trans" />
<xacro:include filename="$(find omni_robot_description)/urdf/omni_robot.gazebo" />
<link name="base_link">
  <inertial>
    <origin xyz="-0.0003866035215641167 1.8970697824213494e-17 0.014105491397793652" rpy="0 0 0"/>
    <mass value="7.526906469202046"/>
    <inertia ixx="0.018693" iyy="0.018693" izz="0.035927" ixy="0.0" iyz="0.0" ixz="3e-06"/>
  </inertial>
  <visual>
    <origin xyz="0 0 0" rpy="0 0 0"/>
    <geometry>
      <mesh filename="file://$(find omni_robot_description)/meshes/base_link.stl" scale="0.001 0.001 0.001"/>
    </geometry>
    <material name="silver"/>
  </visual>
  <collision>
    <origin xyz="0 0 0" rpy="0 0 0"/>
    <geometry>
      <mesh filename="file://$(find omni_robot_description)/meshes/base_link.stl" scale="0.001 0.001 0.001"/>
    </geometry>
  </collision>
</link>

<link name="rim_4_1">
  <inertial>
    <origin xyz="-1.1325643013986204e-07 -0.009000000000000077 3.8076191856070696e-07" rpy="0 0 0"/>
    <mass value="0.14023608587607855"/>
    <inertia ixx="3e-05" iyy="5e-05" izz="3e-05" ixy="-0.0" iyz="0.0" ixz="0.0"/>
  </inertial>
  <visual>
    <origin xyz="0.000403 -0.13 -0.015129" rpy="0 0 0"/>
    <geometry>
      <mesh filename="file://$(find omni_robot_description)/meshes/rim_4_1.stl" scale="0.001 0.001 0.001"/>
    </geometry>
    <material name="silver"/>
  </visual>
  <collision>
    <origin xyz="0.000403 -0.13 -0.015129" rpy="0 0 0"/>
    <geometry>
      <mesh filename="file://$(find omni_robot_description)/meshes/rim_4_1.stl" scale="0.001 0.001 0.001"/>
    </geometry>
  </collision>
</link>

<link name="rim_1_1">
  <inertial>
    <origin xyz="-0.009000113256490583 3.200222004718161e-14 3.8076194701537613e-07" rpy="0 0 0"/>
    <mass value="0.14023608587607866"/>
    <inertia ixx="5e-05" iyy="3e-05" izz="3e-05" ixy="0.0" iyz="0.0" ixz="-0.0"/>
  </inertial>
  <visual>
    <origin xyz="-0.129597 0.0 -0.015129" rpy="0 0 0"/>
    <geometry>
      <mesh filename="file://$(find omni_robot_description)/meshes/rim_1_1.stl" scale="0.001 0.001 0.001"/>
    </geometry>
    <material name="silver"/>
  </visual>
  <collision>
    <origin xyz="-0.129597 0.0 -0.015129" rpy="0 0 0"/>
    <geometry>
      <mesh filename="file://$(find omni_robot_description)/meshes/rim_1_1.stl" scale="0.001 0.001 0.001"/>
    </geometry>
  </collision>
</link>

<link name="rim_2_1">
  <inertial>
    <origin xyz="-1.1325643004054912e-07 0.008999999999999966 3.8076191856070696e-07" rpy="0 0 0"/>
    <mass value="0.1402360858760785"/>
    <inertia ixx="3e-05" iyy="5e-05" izz="3e-05" ixy="-0.0" iyz="0.0" ixz="0.0"/>
  </inertial>
  <visual>
    <origin xyz="0.000403 0.13 -0.015129" rpy="0 0 0"/>
    <geometry>
      <mesh filename="file://$(find omni_robot_description)/meshes/rim_2_1.stl" scale="0.001 0.001 0.001"/>
    </geometry>
    <material name="silver"/>
  </visual>
  <collision>
    <origin xyz="0.000403 0.13 -0.015129" rpy="0 0 0"/>
    <geometry>
      <mesh filename="file://$(find omni_robot_description)/meshes/rim_2_1.stl" scale="0.001 0.001 0.001"/>
    </geometry>
  </collision>
</link>

<link name="rim_3_1">
  <inertial>
    <origin xyz="0.008999886743509697 3.2057903750967407e-14 3.8076194701537613e-07" rpy="0 0 0"/>
    <mass value="0.14023608587607866"/>
    <inertia ixx="5e-05" iyy="3e-05" izz="3e-05" ixy="0.0" iyz="0.0" ixz="-0.0"/>
  </inertial>
  <visual>
    <origin xyz="0.130403 0.0 -0.015129" rpy="0 0 0"/>
    <geometry>
      <mesh filename="file://$(find omni_robot_description)/meshes/rim_3_1.stl" scale="0.001 0.001 0.001"/>
    </geometry>
    <material name="silver"/>
  </visual>
  <collision>
    <origin xyz="0.130403 0.0 -0.015129" rpy="0 0 0"/>
    <geometry>
      <mesh filename="file://$(find omni_robot_description)/meshes/rim_3_1.stl" scale="0.001 0.001 0.001"/>
    </geometry>
  </collision>
</link>

<link name="roller_1_4_1">
  <inertial>
    <origin xyz="-1.1325649029725326e-07 -0.007115848823974879 0.005208793879491304" rpy="0 0 0"/>
    <mass value="0.017098974596301365"/>
    <inertia ixx="1e-06" iyy="0.0" izz="1e-06" ixy="-0.0" iyz="0.0" ixz="-0.0"/>
  </inertial>
  <visual>
    <origin xyz="-0.127347 0.005554 0.008117" rpy="0 0 0"/>
    <geometry>
      <mesh filename="file://$(find omni_robot_description)/meshes/roller_1_4_1.stl" scale="0.001 0.001 0.001"/>
    </geometry>
    <material name="silver"/>
  </visual>
  <collision>
    <origin xyz="-0.127347 0.005554 0.008117" rpy="0 0 0"/>
    <geometry>
      <mesh filename="file://$(find omni_robot_description)/meshes/roller_1_4_1.stl" scale="0.001 0.001 0.001"/>
    </geometry>
  </collision>
</link>

<link name="roller_1_2_1">
  <inertial>
    <origin xyz="-1.1325649040827557e-07 0.007134541942991805 0.005183111093174693" rpy="0 0 0"/>
    <mass value="0.01709897459630134"/>
    <inertia ixx="1e-06" iyy="0.0" izz="1e-06" ixy="0.0" iyz="-0.0" ixz="0.0"/>
  </inertial>
  <visual>
    <origin xyz="-0.127347 -0.005401 0.008146" rpy="0 0 0"/>
    <geometry>
      <mesh filename="file://$(find omni_robot_description)/meshes/roller_1_2_1.stl" scale="0.001 0.001 0.001"/>
    </geometry>
    <material name="silver"/>
  </visual>
  <collision>
    <origin xyz="-0.127347 -0.005401 0.008146" rpy="0 0 0"/>
    <geometry>
      <mesh filename="file://$(find omni_robot_description)/meshes/roller_1_2_1.stl" scale="0.001 0.001 0.001"/>
    </geometry>
  </collision>
</link>

<link name="roller_1_1_1">
  <inertial>
    <origin xyz="-1.1325649035276442e-07 0.0026953505711728963 -0.00839605520024855" rpy="0 0 0"/>
    <mass value="0.01709897459630134"/>
    <inertia ixx="1e-06" iyy="1e-06" izz="0.0" ixy="0.0" iyz="0.0" ixz="0.0"/>
  </inertial>
  <visual>
    <origin xyz="-0.127347 -0.018157 -0.030671" rpy="0 0 0"/>
    <geometry>
      <mesh filename="file://$(find omni_robot_description)/meshes/roller_1_1_1.stl" scale="0.001 0.001 0.001"/>
    </geometry>
    <material name="silver"/>
  </visual>
  <collision>
    <origin xyz="-0.127347 -0.018157 -0.030671" rpy="0 0 0"/>
    <geometry>
      <mesh filename="file://$(find omni_robot_description)/meshes/roller_1_1_1.stl" scale="0.001 0.001 0.001"/>
    </geometry>
  </collision>
</link>

<link name="roller_1_5_1">
  <inertial>
    <origin xyz="-1.1325649046378672e-07 0.00881789545834062 -3.175462523376249e-05" rpy="0 0 0"/>
    <mass value="0.01709897459630137"/>
    <inertia ixx="1e-06" iyy="0.0" izz="1e-06" ixy="-0.0" iyz="0.0" ixz="0.0"/>
  </inertial>
  <visual>
    <origin xyz="-0.127347 0.00917 -0.037201" rpy="0 0 0"/>
    <geometry>
      <mesh filename="file://$(find omni_robot_description)/meshes/roller_1_5_1.stl" scale="0.001 0.001 0.001"/>
    </geometry>
    <material name="silver"/>
  </visual>
  <collision>
    <origin xyz="-0.127347 0.00917 -0.037201" rpy="0 0 0"/>
    <geometry>
      <mesh filename="file://$(find omni_robot_description)/meshes/roller_1_5_1.stl" scale="0.001 0.001 0.001"/>
    </geometry>
  </collision>
</link>

<link name="roller_1_3_1">
  <inertial>
    <origin xyz="-1.132564904915423e-07 0.0027550368544883505 0.00837720216222736" rpy="0 0 0"/>
    <mass value="0.01709897459630136"/>
    <inertia ixx="1e-06" iyy="1e-06" izz="0.0" ixy="0.0" iyz="-0.0" ixz="-0.0"/>
  </inertial>
  <visual>
    <origin xyz="-0.127347 0.023825 -0.013228" rpy="0 0 0"/>
    <geometry>
      <mesh filename="file://$(find omni_robot_description)/meshes/roller_1_3_1.stl" scale="0.001 0.001 0.001"/>
    </geometry>
    <material name="silver"/>
  </visual>
  <collision>
    <origin xyz="-0.127347 0.023825 -0.013228" rpy="0 0 0"/>
    <geometry>
      <mesh filename="file://$(find omni_robot_description)/meshes/roller_1_3_1.stl" scale="0.001 0.001 0.001"/>
    </geometry>
  </collision>
</link>

<link name="roller_1_10_1">
  <inertial>
    <origin xyz="-1.1325649064419796e-07 0.008818602856056328 -3.138634487809787e-05" rpy="0 0 0"/>
    <mass value="0.01709897459630142"/>
    <inertia ixx="1e-06" iyy="0.0" izz="1e-06" ixy="-0.0" iyz="0.0" ixz="0.0"/>
  </inertial>
  <visual>
    <origin xyz="-0.113847 0.009329 0.006876" rpy="0 0 0"/>
    <geometry>
      <mesh filename="file://$(find omni_robot_description)/meshes/roller_1_10_1.stl" scale="0.001 0.001 0.001"/>
    </geometry>
    <material name="silver"/>
  </visual>
  <collision>
    <origin xyz="-0.113847 0.009329 0.006876" rpy="0 0 0"/>
    <geometry>
      <mesh filename="file://$(find omni_robot_description)/meshes/roller_1_10_1.stl" scale="0.001 0.001 0.001"/>
    </geometry>
  </collision>
</link>

<link name="roller_1_8_1">
  <inertial>
    <origin xyz="-1.1325649021398654e-07 0.002755489563608063 0.008377228695167436" rpy="0 0 0"/>
    <mass value="0.0170989745963014"/>
    <inertia ixx="1e-06" iyy="1e-06" izz="0.0" ixy="0.0" iyz="-0.0" ixz="0.0"/>
  </inertial>
  <visual>
    <origin xyz="-0.113847 -0.018045 0.000543" rpy="0 0 0"/>
    <geometry>
      <mesh filename="file://$(find omni_robot_description)/meshes/roller_1_8_1.stl" scale="0.001 0.001 0.001"/>
    </geometry>
    <material name="silver"/>
  </visual>
  <collision>
    <origin xyz="-0.113847 -0.018045 0.000543" rpy="0 0 0"/>
    <geometry>
      <mesh filename="file://$(find omni_robot_description)/meshes/roller_1_8_1.stl" scale="0.001 0.001 0.001"/>
    </geometry>
  </collision>
</link>

<link name="roller_1_9_1">
  <inertial>
    <origin xyz="-1.1325649032500884e-07 -0.007115193323109359 0.005208495938319707" rpy="0 0 0"/>
    <mass value="0.017098974596301383"/>
    <inertia ixx="1e-06" iyy="0.0" izz="1e-06" ixy="0.0" iyz="0.0" ixz="0.0"/>
  </inertial>
  <visual>
    <origin xyz="-0.113847 -0.020481 -0.027449" rpy="0 0 0"/>
    <geometry>
      <mesh filename="file://$(find omni_robot_description)/meshes/roller_1_9_1.stl" scale="0.001 0.001 0.001"/>
    </geometry>
    <material name="silver"/>
  </visual>
  <collision>
    <origin xyz="-0.113847 -0.020481 -0.027449" rpy="0 0 0"/>
    <geometry>
      <mesh filename="file://$(find omni_robot_description)/meshes/roller_1_9_1.stl" scale="0.001 0.001 0.001"/>
    </geometry>
  </collision>
</link>

<link name="roller_1_7_1">
  <inertial>
    <origin xyz="-1.1325649046378672e-07 -0.007152966750229468 -0.005157496233635921" rpy="0 0 0"/>
    <mass value="0.017098974596301355"/>
    <inertia ixx="1e-06" iyy="0.0" izz="1e-06" ixy="0.0" iyz="-0.0" ixz="0.0"/>
  </inertial>
  <visual>
    <origin xyz="-0.113847 0.005387 -0.038415" rpy="0 0 0"/>
    <geometry>
      <mesh filename="file://$(find omni_robot_description)/meshes/roller_1_7_1.stl" scale="0.001 0.001 0.001"/>
    </geometry>
    <material name="silver"/>
  </visual>
  <collision>
    <origin xyz="-0.113847 0.005387 -0.038415" rpy="0 0 0"/>
    <geometry>
      <mesh filename="file://$(find omni_robot_description)/meshes/roller_1_7_1.stl" scale="0.001 0.001 0.001"/>
    </geometry>
  </collision>
</link>

<link name="roller_1_6_1">
  <inertial>
    <origin xyz="-1.1325649040827557e-07 -0.0026645077456347206 0.008406044088050168" rpy="0 0 0"/>
    <mass value="0.017098974596301348"/>
    <inertia ixx="1e-06" iyy="1e-06" izz="0.0" ixy="-0.0" iyz="0.0" ixz="-0.0"/>
  </inertial>
  <visual>
    <origin xyz="-0.113847 0.018163 0.000396" rpy="0 0 0"/>
    <geometry>
      <mesh filename="file://$(find omni_robot_description)/meshes/roller_1_6_1.stl" scale="0.001 0.001 0.001"/>
    </geometry>
    <material name="silver"/>
  </visual>
  <collision>
    <origin xyz="-0.113847 0.018163 0.000396" rpy="0 0 0"/>
    <geometry>
      <mesh filename="file://$(find omni_robot_description)/meshes/roller_1_6_1.stl" scale="0.001 0.001 0.001"/>
    </geometry>
  </collision>
</link>

<link name="roller_4_3_1">
  <inertial>
    <origin xyz="0.00837670814385044 -2.7755575615628914e-17 0.002755417616375008" rpy="0 0 0"/>
    <mass value="0.017098974596301404"/>
    <inertia ixx="0.0" iyy="1e-06" izz="1e-06" ixy="0.0" iyz="-0.0" ixz="-0.0"/>
  </inertial>
  <visual>
    <origin xyz="0.002304 -0.12775 0.008696" rpy="0 0 0"/>
    <geometry>
      <mesh filename="file://$(find omni_robot_description)/meshes/roller_4_3_1.stl" scale="0.001 0.001 0.001"/>
    </geometry>
    <material name="silver"/>
  </visual>
  <collision>
    <origin xyz="0.002304 -0.12775 0.008696" rpy="0 0 0"/>
    <geometry>
      <mesh filename="file://$(find omni_robot_description)/meshes/roller_4_3_1.stl" scale="0.001 0.001 0.001"/>
    </geometry>
  </collision>
</link>

<link name="roller_4_4_1">
  <inertial>
    <origin xyz="0.005209299861114333 -8.326672684688674e-17 -0.007115468062088329" rpy="0 0 0"/>
    <mass value="0.017098974596301355"/>
    <inertia ixx="1e-06" iyy="1e-06" izz="0.0" ixy="0.0" iyz="-0.0" ixz="0.0"/>
  </inertial>
  <visual>
    <origin xyz="0.02365 -0.12775 -0.009575" rpy="0 0 0"/>
    <geometry>
      <mesh filename="file://$(find omni_robot_description)/meshes/roller_4_4_1.stl" scale="0.001 0.001 0.001"/>
    </geometry>
    <material name="silver"/>
  </visual>
  <collision>
    <origin xyz="0.02365 -0.12775 -0.009575" rpy="0 0 0"/>
    <geometry>
      <mesh filename="file://$(find omni_robot_description)/meshes/roller_4_4_1.stl" scale="0.001 0.001 0.001"/>
    </geometry>
  </collision>
</link>

<link name="roller_4_2_1">
  <inertial>
    <origin xyz="-0.0051577764251810165 -5.551115123125783e-17 -0.007153053298141379" rpy="0 0 0"/>
    <mass value="0.01709897459630137"/>
    <inertia ixx="1e-06" iyy="1e-06" izz="0.0" ixy="0.0" iyz="-0.0" ixz="-0.0"/>
  </inertial>
  <visual>
    <origin xyz="0.012869 -0.12775 -0.035522" rpy="0 0 0"/>
    <geometry>
      <mesh filename="file://$(find omni_robot_description)/meshes/roller_4_2_1.stl" scale="0.001 0.001 0.001"/>
    </geometry>
    <material name="silver"/>
  </visual>
  <collision>
    <origin xyz="0.012869 -0.12775 -0.035522" rpy="0 0 0"/>
    <geometry>
      <mesh filename="file://$(find omni_robot_description)/meshes/roller_4_2_1.stl" scale="0.001 0.001 0.001"/>
    </geometry>
  </collision>
</link>

<link name="roller_4_1_1">
  <inertial>
    <origin xyz="-0.008396549218625916 -1.1102230246251565e-16 0.0026947313330595232" rpy="0 0 0"/>
    <mass value="0.017098974596301365"/>
    <inertia ixx="0.0" iyy="1e-06" izz="1e-06" ixy="-0.0" iyz="-0.0" ixz="0.0"/>
  </inertial>
  <visual>
    <origin xyz="-0.015139 -0.12775 -0.033287" rpy="0 0 0"/>
    <geometry>
      <mesh filename="file://$(find omni_robot_description)/meshes/roller_4_1_1.stl" scale="0.001 0.001 0.001"/>
    </geometry>
    <material name="silver"/>
  </visual>
  <collision>
    <origin xyz="-0.015139 -0.12775 -0.033287" rpy="0 0 0"/>
    <geometry>
      <mesh filename="file://$(find omni_robot_description)/meshes/roller_4_1_1.stl" scale="0.001 0.001 0.001"/>
    </geometry>
  </collision>
</link>

<link name="roller_4_5_1">
  <inertial>
    <origin xyz="-3.124864361087054e-05 0.0 0.008818276220227603" rpy="0 0 0"/>
    <mass value="0.01709897459630136"/>
    <inertia ixx="1e-06" iyy="1e-06" izz="0.0" ixy="-0.0" iyz="0.0" ixz="0.0"/>
  </inertial>
  <visual>
    <origin xyz="-0.021668 -0.12775 -0.005959" rpy="0 0 0"/>
    <geometry>
      <mesh filename="file://$(find omni_robot_description)/meshes/roller_4_5_1.stl" scale="0.001 0.001 0.001"/>
    </geometry>
    <material name="silver"/>
  </visual>
  <collision>
    <origin xyz="-0.021668 -0.12775 -0.005959" rpy="0 0 0"/>
    <geometry>
      <mesh filename="file://$(find omni_robot_description)/meshes/roller_4_5_1.stl" scale="0.001 0.001 0.001"/>
    </geometry>
  </collision>
</link>

<link name="roller_4_9_1">
  <inertial>
    <origin xyz="0.00520900191994236 -1.249000902703301e-16 -0.007115812561222651" rpy="0 0 0"/>
    <mass value="0.017098974596301404"/>
    <inertia ixx="1e-06" iyy="1e-06" izz="0.0" ixy="-0.0" iyz="-0.0" ixz="0.0"/>
  </inertial>
  <visual>
    <origin xyz="-0.011916 -0.11425 -0.035611" rpy="0 0 0"/>
    <geometry>
      <mesh filename="file://$(find omni_robot_description)/meshes/roller_4_9_1.stl" scale="0.001 0.001 0.001"/>
    </geometry>
    <material name="silver"/>
  </visual>
  <collision>
    <origin xyz="-0.011916 -0.11425 -0.035611" rpy="0 0 0"/>
    <geometry>
      <mesh filename="file://$(find omni_robot_description)/meshes/roller_4_9_1.stl" scale="0.001 0.001 0.001"/>
    </geometry>
  </collision>
</link>

<link name="roller_4_7_1">
  <inertial>
    <origin xyz="-0.005157990252012985 -8.326672684688674e-17 -0.007152585988342746" rpy="0 0 0"/>
    <mass value="0.01709897459630135"/>
    <inertia ixx="1e-06" iyy="1e-06" izz="0.0" ixy="-0.0" iyz="-0.0" ixz="-0.0"/>
  </inertial>
  <visual>
    <origin xyz="-0.022883 -0.11425 -0.009742" rpy="0 0 0"/>
    <geometry>
      <mesh filename="file://$(find omni_robot_description)/meshes/roller_4_7_1.stl" scale="0.001 0.001 0.001"/>
    </geometry>
    <material name="silver"/>
  </visual>
  <collision>
    <origin xyz="-0.022883 -0.11425 -0.009742" rpy="0 0 0"/>
    <geometry>
      <mesh filename="file://$(find omni_robot_description)/meshes/roller_4_7_1.stl" scale="0.001 0.001 0.001"/>
    </geometry>
  </collision>
</link>

<link name="roller_4_6_1">
  <inertial>
    <origin xyz="-0.008396432263917545 -8.326672684688674e-17 0.0026944484155603937" rpy="0 0 0"/>
    <mass value="0.017098974596301362"/>
    <inertia ixx="0.0" iyy="1e-06" izz="1e-06" ixy="0.0" iyz="0.0" ixz="0.0"/>
  </inertial>
  <visual>
    <origin xyz="-0.001669 -0.11425 0.008681" rpy="0 0 0"/>
    <geometry>
      <mesh filename="file://$(find omni_robot_description)/meshes/roller_4_6_1.stl" scale="0.001 0.001 0.001"/>
    </geometry>
    <material name="silver"/>
  </visual>
  <collision>
    <origin xyz="-0.001669 -0.11425 0.008681" rpy="0 0 0"/>
    <geometry>
      <mesh filename="file://$(find omni_robot_description)/meshes/roller_4_6_1.stl" scale="0.001 0.001 0.001"/>
    </geometry>
  </collision>
</link>

<link name="roller_4_10_1">
  <inertial>
    <origin xyz="-3.18803632551809e-05 -1.3877787807814457e-17 0.00881798361794275" rpy="0 0 0"/>
    <mass value="0.017098974596301338"/>
    <inertia ixx="1e-06" iyy="1e-06" izz="0.0" ixy="0.0" iyz="-0.0" ixz="0.0"/>
  </inertial>
  <visual>
    <origin xyz="0.022408 -0.11425 -0.005801" rpy="0 0 0"/>
    <geometry>
      <mesh filename="file://$(find omni_robot_description)/meshes/roller_4_10_1.stl" scale="0.001 0.001 0.001"/>
    </geometry>
    <material name="silver"/>
  </visual>
  <collision>
    <origin xyz="0.022408 -0.11425 -0.005801" rpy="0 0 0"/>
    <geometry>
      <mesh filename="file://$(find omni_robot_description)/meshes/roller_4_10_1.stl" scale="0.001 0.001 0.001"/>
    </geometry>
  </collision>
</link>

<link name="roller_4_8_1">
  <inertial>
    <origin xyz="0.008376734676790173 9.71445146547012e-17 0.00275487032549461" rpy="0 0 0"/>
    <mass value="0.01709897459630136"/>
    <inertia ixx="0.0" iyy="1e-06" izz="1e-06" ixy="-0.0" iyz="0.0" ixz="-0.0"/>
  </inertial>
  <visual>
    <origin xyz="0.016075 -0.11425 -0.033175" rpy="0 0 0"/>
    <geometry>
      <mesh filename="file://$(find omni_robot_description)/meshes/roller_4_8_1.stl" scale="0.001 0.001 0.001"/>
    </geometry>
    <material name="silver"/>
  </visual>
  <collision>
    <origin xyz="0.016075 -0.11425 -0.033175" rpy="0 0 0"/>
    <geometry>
      <mesh filename="file://$(find omni_robot_description)/meshes/roller_4_8_1.stl" scale="0.001 0.001 0.001"/>
    </geometry>
  </collision>
</link>

<link name="roller_3_10_1">
  <inertial>
    <origin xyz="-1.1325649032500884e-07 0.008818602856056346 -3.138634487807792e-05" rpy="0 0 0"/>
    <mass value="0.0170989745963014"/>
    <inertia ixx="1e-06" iyy="0.0" izz="1e-06" ixy="-0.0" iyz="0.0" ixz="-0.0"/>
  </inertial>
  <visual>
    <origin xyz="0.128153 0.009329 0.006876" rpy="0 0 0"/>
    <geometry>
      <mesh filename="file://$(find omni_robot_description)/meshes/roller_3_10_1.stl" scale="0.001 0.001 0.001"/>
    </geometry>
    <material name="silver"/>
  </visual>
  <collision>
    <origin xyz="0.128153 0.009329 0.006876" rpy="0 0 0"/>
    <geometry>
      <mesh filename="file://$(find omni_robot_description)/meshes/roller_3_10_1.stl" scale="0.001 0.001 0.001"/>
    </geometry>
  </collision>
</link>

<link name="roller_3_6_1">
  <inertial>
    <origin xyz="-1.1325649057480902e-07 0.0026950676536738327 -0.008396938245540744" rpy="0 0 0"/>
    <mass value="0.017098974596301327"/>
    <inertia ixx="1e-06" iyy="1e-06" izz="0.0" ixy="0.0" iyz="0.0" ixz="-0.0"/>
  </inertial>
  <visual>
    <origin xyz="0.128153 0.023811 -0.017202" rpy="0 0 0"/>
    <geometry>
      <mesh filename="file://$(find omni_robot_description)/meshes/roller_3_6_1.stl" scale="0.001 0.001 0.001"/>
    </geometry>
    <material name="silver"/>
  </visual>
  <collision>
    <origin xyz="0.128153 0.023811 -0.017202" rpy="0 0 0"/>
    <geometry>
      <mesh filename="file://$(find omni_robot_description)/meshes/roller_3_6_1.stl" scale="0.001 0.001 0.001"/>
    </geometry>
  </collision>
</link>

<link name="roller_3_7_1">
  <inertial>
    <origin xyz="-1.1325649051929787e-07 -0.007152966750229421 -0.005157496233635921" rpy="0 0 0"/>
    <mass value="0.017098974596301355"/>
    <inertia ixx="1e-06" iyy="0.0" izz="1e-06" ixy="0.0" iyz="-0.0" ixz="0.0"/>
  </inertial>
  <visual>
    <origin xyz="0.128153 0.005387 -0.038415" rpy="0 0 0"/>
    <geometry>
      <mesh filename="file://$(find omni_robot_description)/meshes/roller_3_7_1.stl" scale="0.001 0.001 0.001"/>
    </geometry>
    <material name="silver"/>
  </visual>
  <collision>
    <origin xyz="0.128153 0.005387 -0.038415" rpy="0 0 0"/>
    <geometry>
      <mesh filename="file://$(find omni_robot_description)/meshes/roller_3_7_1.stl" scale="0.001 0.001 0.001"/>
    </geometry>
  </collision>
</link>

<link name="roller_3_9_1">
  <inertial>
    <origin xyz="-1.132564907135869e-07 -0.007115193323109342 0.005208495938319686" rpy="0 0 0"/>
    <mass value="0.01709897459630138"/>
    <inertia ixx="1e-06" iyy="0.0" izz="1e-06" ixy="-0.0" iyz="0.0" ixz="-0.0"/>
  </inertial>
  <visual>
    <origin xyz="0.128153 -0.020481 -0.027449" rpy="0 0 0"/>
    <geometry>
      <mesh filename="file://$(find omni_robot_description)/meshes/roller_3_9_1.stl" scale="0.001 0.001 0.001"/>
    </geometry>
    <material name="silver"/>
  </visual>
  <collision>
    <origin xyz="0.128153 -0.020481 -0.027449" rpy="0 0 0"/>
    <geometry>
      <mesh filename="file://$(find omni_robot_description)/meshes/roller_3_9_1.stl" scale="0.001 0.001 0.001"/>
    </geometry>
  </collision>
</link>

<link name="roller_3_8_1">
  <inertial>
    <origin xyz="-1.132564908246092e-07 0.0027554895636080733 0.00837722869516742" rpy="0 0 0"/>
    <mass value="0.017098974596301383"/>
    <inertia ixx="1e-06" iyy="1e-06" izz="0.0" ixy="-0.0" iyz="-0.0" ixz="-0.0"/>
  </inertial>
  <visual>
    <origin xyz="0.128153 -0.018045 0.000543" rpy="0 0 0"/>
    <geometry>
      <mesh filename="file://$(find omni_robot_description)/meshes/roller_3_8_1.stl" scale="0.001 0.001 0.001"/>
    </geometry>
    <material name="silver"/>
  </visual>
  <collision>
    <origin xyz="0.128153 -0.018045 0.000543" rpy="0 0 0"/>
    <geometry>
      <mesh filename="file://$(find omni_robot_description)/meshes/roller_3_8_1.stl" scale="0.001 0.001 0.001"/>
    </geometry>
  </collision>
</link>

<link name="roller_3_5_1">
  <inertial>
    <origin xyz="-1.1325649053317566e-07 0.008817895458340644 -3.1754625233727796e-05" rpy="0 0 0"/>
    <mass value="0.017098974596301365"/>
    <inertia ixx="1e-06" iyy="0.0" izz="1e-06" ixy="-0.0" iyz="0.0" ixz="-0.0"/>
  </inertial>
  <visual>
    <origin xyz="0.114653 0.00917 -0.037201" rpy="0 0 0"/>
    <geometry>
      <mesh filename="file://$(find omni_robot_description)/meshes/roller_3_5_1.stl" scale="0.001 0.001 0.001"/>
    </geometry>
    <material name="silver"/>
  </visual>
  <collision>
    <origin xyz="0.114653 0.00917 -0.037201" rpy="0 0 0"/>
    <geometry>
      <mesh filename="file://$(find omni_robot_description)/meshes/roller_3_5_1.stl" scale="0.001 0.001 0.001"/>
    </geometry>
  </collision>
</link>

<link name="roller_3_1_1">
  <inertial>
    <origin xyz="-1.1325649053317566e-07 0.002695350571172931 -0.00839605520024855" rpy="0 0 0"/>
    <mass value="0.017098974596301345"/>
    <inertia ixx="1e-06" iyy="1e-06" izz="0.0" ixy="-0.0" iyz="0.0" ixz="0.0"/>
  </inertial>
  <visual>
    <origin xyz="0.114653 -0.018157 -0.030671" rpy="0 0 0"/>
    <geometry>
      <mesh filename="file://$(find omni_robot_description)/meshes/roller_3_1_1.stl" scale="0.001 0.001 0.001"/>
    </geometry>
    <material name="silver"/>
  </visual>
  <collision>
    <origin xyz="0.114653 -0.018157 -0.030671" rpy="0 0 0"/>
    <geometry>
      <mesh filename="file://$(find omni_robot_description)/meshes/roller_3_1_1.stl" scale="0.001 0.001 0.001"/>
    </geometry>
  </collision>
</link>

<link name="roller_3_2_1">
  <inertial>
    <origin xyz="-1.1325649035276442e-07 -0.007152434060027871 -0.005157282406803882" rpy="0 0 0"/>
    <mass value="0.017098974596301428"/>
    <inertia ixx="1e-06" iyy="0.0" izz="1e-06" ixy="0.0" iyz="-0.0" ixz="-0.0"/>
  </inertial>
  <visual>
    <origin xyz="0.114653 -0.020392 -0.002663" rpy="0 0 0"/>
    <geometry>
      <mesh filename="file://$(find omni_robot_description)/meshes/roller_3_2_1.stl" scale="0.001 0.001 0.001"/>
    </geometry>
    <material name="silver"/>
  </visual>
  <collision>
    <origin xyz="0.114653 -0.020392 -0.002663" rpy="0 0 0"/>
    <geometry>
      <mesh filename="file://$(find omni_robot_description)/meshes/roller_3_2_1.stl" scale="0.001 0.001 0.001"/>
    </geometry>
  </collision>
</link>

<link name="roller_3_4_1">
  <inertial>
    <origin xyz="-1.1325649069970911e-07 -0.00711584882397483 0.005208793879491304" rpy="0 0 0"/>
    <mass value="0.017098974596301365"/>
    <inertia ixx="1e-06" iyy="0.0" izz="1e-06" ixy="0.0" iyz="0.0" ixz="0.0"/>
  </inertial>
  <visual>
    <origin xyz="0.114653 0.005554 0.008117" rpy="0 0 0"/>
    <geometry>
      <mesh filename="file://$(find omni_robot_description)/meshes/roller_3_4_1.stl" scale="0.001 0.001 0.001"/>
    </geometry>
    <material name="silver"/>
  </visual>
  <collision>
    <origin xyz="0.114653 0.005554 0.008117" rpy="0 0 0"/>
    <geometry>
      <mesh filename="file://$(find omni_robot_description)/meshes/roller_3_4_1.stl" scale="0.001 0.001 0.001"/>
    </geometry>
  </collision>
</link>

<link name="roller_3_3_1">
  <inertial>
    <origin xyz="-1.1325649039439778e-07 0.0027550368544883505 0.008377202162227346" rpy="0 0 0"/>
    <mass value="0.01709897459630136"/>
    <inertia ixx="1e-06" iyy="1e-06" izz="0.0" ixy="-0.0" iyz="-0.0" ixz="0.0"/>
  </inertial>
  <visual>
    <origin xyz="0.114653 0.023825 -0.013228" rpy="0 0 0"/>
    <geometry>
      <mesh filename="file://$(find omni_robot_description)/meshes/roller_3_3_1.stl" scale="0.001 0.001 0.001"/>
    </geometry>
    <material name="silver"/>
  </visual>
  <collision>
    <origin xyz="0.114653 0.023825 -0.013228" rpy="0 0 0"/>
    <geometry>
      <mesh filename="file://$(find omni_robot_description)/meshes/roller_3_3_1.stl" scale="0.001 0.001 0.001"/>
    </geometry>
  </collision>
</link>

<link name="roller_2_6_1">
  <inertial>
    <origin xyz="-0.008396432263917678 -8.326672684688674e-17 0.0026944484155604093" rpy="0 0 0"/>
    <mass value="0.017098974596301355"/>
    <inertia ixx="0.0" iyy="1e-06" izz="1e-06" ixy="0.0" iyz="-0.0" ixz="0.0"/>
  </inertial>
  <visual>
    <origin xyz="-0.001669 0.12775 0.008681" rpy="0 0 0"/>
    <geometry>
      <mesh filename="file://$(find omni_robot_description)/meshes/roller_2_6_1.stl" scale="0.001 0.001 0.001"/>
    </geometry>
    <material name="silver"/>
  </visual>
  <collision>
    <origin xyz="-0.001669 0.12775 0.008681" rpy="0 0 0"/>
    <geometry>
      <mesh filename="file://$(find omni_robot_description)/meshes/roller_2_6_1.stl" scale="0.001 0.001 0.001"/>
    </geometry>
  </collision>
</link>

<link name="roller_2_7_1">
  <inertial>
    <origin xyz="-0.005157990252012967 -4.718447854656915e-16 -0.007152585988342886" rpy="0 0 0"/>
    <mass value="0.017098974596301397"/>
    <inertia ixx="1e-06" iyy="1e-06" izz="0.0" ixy="-0.0" iyz="-0.0" ixz="-0.0"/>
  </inertial>
  <visual>
    <origin xyz="-0.022883 0.12775 -0.009742" rpy="0 0 0"/>
    <geometry>
      <mesh filename="file://$(find omni_robot_description)/meshes/roller_2_7_1.stl" scale="0.001 0.001 0.001"/>
    </geometry>
    <material name="silver"/>
  </visual>
  <collision>
    <origin xyz="-0.022883 0.12775 -0.009742" rpy="0 0 0"/>
    <geometry>
      <mesh filename="file://$(find omni_robot_description)/meshes/roller_2_7_1.stl" scale="0.001 0.001 0.001"/>
    </geometry>
  </collision>
</link>

<link name="roller_2_9_1">
  <inertial>
    <origin xyz="0.005209001919942693 2.7755575615628914e-17 -0.007115812561222765" rpy="0 0 0"/>
    <mass value="0.017098974596301365"/>
    <inertia ixx="1e-06" iyy="1e-06" izz="0.0" ixy="0.0" iyz="0.0" ixz="0.0"/>
  </inertial>
  <visual>
    <origin xyz="-0.011916 0.12775 -0.035611" rpy="0 0 0"/>
    <geometry>
      <mesh filename="file://$(find omni_robot_description)/meshes/roller_2_9_1.stl" scale="0.001 0.001 0.001"/>
    </geometry>
    <material name="silver"/>
  </visual>
  <collision>
    <origin xyz="-0.011916 0.12775 -0.035611" rpy="0 0 0"/>
    <geometry>
      <mesh filename="file://$(find omni_robot_description)/meshes/roller_2_9_1.stl" scale="0.001 0.001 0.001"/>
    </geometry>
  </collision>
</link>

<link name="roller_2_8_1">
  <inertial>
    <origin xyz="0.008376734676790459 -3.608224830031759e-16 0.002754870325494728" rpy="0 0 0"/>
    <mass value="0.017098974596301338"/>
    <inertia ixx="0.0" iyy="1e-06" izz="1e-06" ixy="0.0" iyz="-0.0" ixz="-0.0"/>
  </inertial>
  <visual>
    <origin xyz="0.016075 0.12775 -0.033175" rpy="0 0 0"/>
    <geometry>
      <mesh filename="file://$(find omni_robot_description)/meshes/roller_2_8_1.stl" scale="0.001 0.001 0.001"/>
    </geometry>
    <material name="silver"/>
  </visual>
  <collision>
    <origin xyz="0.016075 0.12775 -0.033175" rpy="0 0 0"/>
    <geometry>
      <mesh filename="file://$(find omni_robot_description)/meshes/roller_2_8_1.stl" scale="0.001 0.001 0.001"/>
    </geometry>
  </collision>
</link>

<link name="roller_2_10_1">
  <inertial>
    <origin xyz="-3.188036325511151e-05 -1.3877787807814457e-16 0.008817983617942952" rpy="0 0 0"/>
    <mass value="0.01709897459630138"/>
    <inertia ixx="1e-06" iyy="1e-06" izz="0.0" ixy="-0.0" iyz="0.0" ixz="0.0"/>
  </inertial>
  <visual>
    <origin xyz="0.022408 0.12775 -0.005801" rpy="0 0 0"/>
    <geometry>
      <mesh filename="file://$(find omni_robot_description)/meshes/roller_2_10_1.stl" scale="0.001 0.001 0.001"/>
    </geometry>
    <material name="silver"/>
  </visual>
  <collision>
    <origin xyz="0.022408 0.12775 -0.005801" rpy="0 0 0"/>
    <geometry>
      <mesh filename="file://$(find omni_robot_description)/meshes/roller_2_10_1.stl" scale="0.001 0.001 0.001"/>
    </geometry>
  </collision>
</link>

<link name="roller_2_1_1">
  <inertial>
    <origin xyz="-0.008396549218625579 1.3877787807814457e-17 0.0026947313330594608" rpy="0 0 0"/>
    <mass value="0.01709897459630137"/>
    <inertia ixx="0.0" iyy="1e-06" izz="1e-06" ixy="0.0" iyz="0.0" ixz="0.0"/>
  </inertial>
  <visual>
    <origin xyz="-0.015139 0.11425 -0.033287" rpy="0 0 0"/>
    <geometry>
      <mesh filename="file://$(find omni_robot_description)/meshes/roller_2_1_1.stl" scale="0.001 0.001 0.001"/>
    </geometry>
    <material name="silver"/>
  </visual>
  <collision>
    <origin xyz="-0.015139 0.11425 -0.033287" rpy="0 0 0"/>
    <geometry>
      <mesh filename="file://$(find omni_robot_description)/meshes/roller_2_1_1.stl" scale="0.001 0.001 0.001"/>
    </geometry>
  </collision>
</link>

<link name="roller_2_2_1">
  <inertial>
    <origin xyz="-0.005157776425180756 1.3877787807814457e-17 -0.007153053298141272" rpy="0 0 0"/>
    <mass value="0.01709897459630136"/>
    <inertia ixx="1e-06" iyy="1e-06" izz="0.0" ixy="-0.0" iyz="0.0" ixz="-0.0"/>
  </inertial>
  <visual>
    <origin xyz="0.012869 0.11425 -0.035522" rpy="0 0 0"/>
    <geometry>
      <mesh filename="file://$(find omni_robot_description)/meshes/roller_2_2_1.stl" scale="0.001 0.001 0.001"/>
    </geometry>
    <material name="silver"/>
  </visual>
  <collision>
    <origin xyz="0.012869 0.11425 -0.035522" rpy="0 0 0"/>
    <geometry>
      <mesh filename="file://$(find omni_robot_description)/meshes/roller_2_2_1.stl" scale="0.001 0.001 0.001"/>
    </geometry>
  </collision>
</link>

<link name="roller_2_4_1">
  <inertial>
    <origin xyz="0.00520929986111433 -1.3877787807814457e-17 -0.007115468062088277" rpy="0 0 0"/>
    <mass value="0.017098974596301365"/>
    <inertia ixx="1e-06" iyy="1e-06" izz="0.0" ixy="-0.0" iyz="-0.0" ixz="0.0"/>
  </inertial>
  <visual>
    <origin xyz="0.02365 0.11425 -0.009575" rpy="0 0 0"/>
    <geometry>
      <mesh filename="file://$(find omni_robot_description)/meshes/roller_2_4_1.stl" scale="0.001 0.001 0.001"/>
    </geometry>
    <material name="silver"/>
  </visual>
  <collision>
    <origin xyz="0.02365 0.11425 -0.009575" rpy="0 0 0"/>
    <geometry>
      <mesh filename="file://$(find omni_robot_description)/meshes/roller_2_4_1.stl" scale="0.001 0.001 0.001"/>
    </geometry>
  </collision>
</link>

<link name="roller_2_3_1">
  <inertial>
    <origin xyz="0.008376708143850334 -1.942890293094024e-16 0.0027554176163749316" rpy="0 0 0"/>
    <mass value="0.01709897459630139"/>
    <inertia ixx="0.0" iyy="1e-06" izz="1e-06" ixy="-0.0" iyz="-0.0" ixz="-0.0"/>
  </inertial>
  <visual>
    <origin xyz="0.002304 0.11425 0.008696" rpy="0 0 0"/>
    <geometry>
      <mesh filename="file://$(find omni_robot_description)/meshes/roller_2_3_1.stl" scale="0.001 0.001 0.001"/>
    </geometry>
    <material name="silver"/>
  </visual>
  <collision>
    <origin xyz="0.002304 0.11425 0.008696" rpy="0 0 0"/>
    <geometry>
      <mesh filename="file://$(find omni_robot_description)/meshes/roller_2_3_1.stl" scale="0.001 0.001 0.001"/>
    </geometry>
  </collision>
</link>

<link name="roller_2_5_1">
  <inertial>
    <origin xyz="-3.1248643610717886e-05 -9.71445146547012e-17 0.00881827622022727" rpy="0 0 0"/>
    <mass value="0.017098974596301345"/>
    <inertia ixx="1e-06" iyy="1e-06" izz="0.0" ixy="0.0" iyz="-0.0" ixz="0.0"/>
  </inertial>
  <visual>
    <origin xyz="-0.021668 0.11425 -0.005959" rpy="0 0 0"/>
    <geometry>
      <mesh filename="file://$(find omni_robot_description)/meshes/roller_2_5_1.stl" scale="0.001 0.001 0.001"/>
    </geometry>
    <material name="silver"/>
  </visual>
  <collision>
    <origin xyz="-0.021668 0.11425 -0.005959" rpy="0 0 0"/>
    <geometry>
      <mesh filename="file://$(find omni_robot_description)/meshes/roller_2_5_1.stl" scale="0.001 0.001 0.001"/>
    </geometry>
  </collision>
</link>

<link name="lidar_link_1">
  <inertial>
    <origin xyz="1.247849806060782e-15 7.154338888081818e-16 -0.007499619238113479" rpy="0 0 0"/>
    <mass value="0.5363876756922872"/>
    <inertia ixx="0.000204" iyy="0.000204" izz="0.000389" ixy="0.0" iyz="0.0" ixz="0.0"/>
  </inertial>
  <visual>
    <origin xyz="-0.0 0.0 0.019871" rpy="0 0 0"/>
    <geometry>
      <mesh filename="file://$(find omni_robot_description)/meshes/lidar_link_1.stl" scale="0.001 0.001 0.001"/>
    </geometry>
    <material name="silver"/>
  </visual>
  <collision>
    <origin xyz="-0.0 0.0 0.019871" rpy="0 0 0"/>
    <geometry>
      <mesh filename="file://$(find omni_robot_description)/meshes/lidar_link_1.stl" scale="0.001 0.001 0.001"/>
    </geometry>
  </collision>
</link>

<link name="imu_link_1">
  <inertial>
    <origin xyz="0.005303187602408388 0.005303300858899032 3.8076188724374405e-07" rpy="0 0 0"/>
    <mass value="0.026334958428243183"/>
    <inertia ixx="1e-06" iyy="1e-06" izz="1e-06" ixy="0.0" iyz="-0.0" ixz="-0.0"/>
  </inertial>
  <visual>
    <origin xyz="-0.064597 -0.065 -0.015129" rpy="0 0 0"/>
    <geometry>
      <mesh filename="file://$(find omni_robot_description)/meshes/imu_link_1.stl" scale="0.001 0.001 0.001"/>
    </geometry>
    <material name="silver"/>
  </visual>
  <collision>
    <origin xyz="-0.064597 -0.065 -0.015129" rpy="0 0 0"/>
    <geometry>
      <mesh filename="file://$(find omni_robot_description)/meshes/imu_link_1.stl" scale="0.001 0.001 0.001"/>
    </geometry>
  </collision>
</link>

<joint name="Revolute 1" type="continuous">
  <origin xyz="-0.000403 0.13 0.015129" rpy="0 0 0"/>
  <parent link="base_link"/>
  <child link="rim_4_1"/>
  <axis xyz="0.0 1.0 -0.0"/>
</joint>

<joint name="Revolute 2" type="continuous">
  <origin xyz="0.129597 0.0 0.015129" rpy="0 0 0"/>
  <parent link="base_link"/>
  <child link="rim_1_1"/>
  <axis xyz="1.0 -0.0 0.0"/>
</joint>

<joint name="Revolute 3" type="continuous">
  <origin xyz="-0.000403 -0.13 0.015129" rpy="0 0 0"/>
  <parent link="base_link"/>
  <child link="rim_2_1"/>
  <axis xyz="-0.0 -1.0 -0.0"/>
</joint>

<joint name="Revolute 4" type="continuous">
  <origin xyz="-0.130403 0.0 0.015129" rpy="0 0 0"/>
  <parent link="base_link"/>
  <child link="rim_3_1"/>
  <axis xyz="-1.0 0.0 -0.0"/>
</joint>

<joint name="Revolute 5" type="continuous">
  <origin xyz="-0.00225 -0.005554 -0.023246" rpy="0 0 0"/>
  <parent link="rim_1_1"/>
  <child link="roller_1_4_1"/>
  <axis xyz="-0.0 0.806901 -0.590687"/>
</joint>

<joint name="Revolute 6" type="continuous">
  <origin xyz="-0.00225 0.005401 -0.023275" rpy="0 0 0"/>
  <parent link="rim_1_1"/>
  <child link="roller_1_2_1"/>
  <axis xyz="0.0 -0.809017 -0.587785"/>
</joint>

<joint name="Revolute 7" type="continuous">
  <origin xyz="-0.00225 0.018157 0.015542" rpy="0 0 0"/>
  <parent link="rim_1_1"/>
  <child link="roller_1_1_1"/>
  <axis xyz="0.0 -0.305599 0.95216"/>
</joint>

<joint name="Revolute 8" type="continuous">
  <origin xyz="-0.00225 -0.00917 0.022072" rpy="0 0 0"/>
  <parent link="rim_1_1"/>
  <child link="roller_1_5_1"/>
  <axis xyz="0.0 -0.999994 0.003591"/>
</joint>

<joint name="Revolute 9" type="continuous">
  <origin xyz="-0.00225 -0.023825 -0.001901" rpy="0 0 0"/>
  <parent link="rim_1_1"/>
  <child link="roller_1_3_1"/>
  <axis xyz="0.0 -0.312431 -0.949941"/>
</joint>

<joint name="Revolute 10" type="continuous">
  <origin xyz="-0.01575 -0.009329 -0.022005" rpy="0 0 0"/>
  <parent link="rim_1_1"/>
  <child link="roller_1_10_1"/>
  <axis xyz="0.0 -0.999994 0.003591"/>
</joint>

<joint name="Revolute 11" type="continuous">
  <origin xyz="-0.01575 0.018045 -0.015672" rpy="0 0 0"/>
  <parent link="rim_1_1"/>
  <child link="roller_1_8_1"/>
  <axis xyz="0.0 -0.312431 -0.949941"/>
</joint>

<joint name="Revolute 12" type="continuous">
  <origin xyz="-0.01575 0.020481 0.01232" rpy="0 0 0"/>
  <parent link="rim_1_1"/>
  <child link="roller_1_9_1"/>
  <axis xyz="-0.0 0.806901 -0.590687"/>
</joint>

<joint name="Revolute 13" type="continuous">
  <origin xyz="-0.01575 -0.005387 0.023286" rpy="0 0 0"/>
  <parent link="rim_1_1"/>
  <child link="roller_1_7_1"/>
  <axis xyz="-0.0 0.811123 0.584876"/>
</joint>

<joint name="Revolute 14" type="continuous">
  <origin xyz="-0.01575 -0.018163 -0.015525" rpy="0 0 0"/>
  <parent link="rim_1_1"/>
  <child link="roller_1_6_1"/>
  <axis xyz="-0.0 0.302178 -0.953252"/>
</joint>

<joint name="Revolute 15" type="continuous">
  <origin xyz="-0.001901 -0.00225 -0.023825" rpy="0 0 0"/>
  <parent link="rim_4_1"/>
  <child link="roller_4_3_1"/>
  <axis xyz="-0.949941 0.0 -0.312431"/>
</joint>

<joint name="Revolute 16" type="continuous">
  <origin xyz="-0.023247 -0.00225 -0.005554" rpy="0 0 0"/>
  <parent link="rim_4_1"/>
  <child link="roller_4_4_1"/>
  <axis xyz="-0.590687 0.0 0.806901"/>
</joint>

<joint name="Revolute 17" type="continuous">
  <origin xyz="-0.012466 -0.00225 0.020393" rpy="0 0 0"/>
  <parent link="rim_4_1"/>
  <child link="roller_4_2_1"/>
  <axis xyz="0.584876 -0.0 0.811123"/>
</joint>

<joint name="Revolute 18" type="continuous">
  <origin xyz="0.015542 -0.00225 0.018158" rpy="0 0 0"/>
  <parent link="rim_4_1"/>
  <child link="roller_4_1_1"/>
  <axis xyz="0.95216 -0.0 -0.305599"/>
</joint>

<joint name="Revolute 19" type="continuous">
  <origin xyz="0.022071 -0.00225 -0.00917" rpy="0 0 0"/>
  <parent link="rim_4_1"/>
  <child link="roller_4_5_1"/>
  <axis xyz="0.003591 -0.0 -0.999994"/>
</joint>

<joint name="Revolute 20" type="continuous">
  <origin xyz="0.012319 -0.01575 0.020482" rpy="0 0 0"/>
  <parent link="rim_4_1"/>
  <child link="roller_4_9_1"/>
  <axis xyz="-0.590687 0.0 0.806901"/>
</joint>

<joint name="Revolute 21" type="continuous">
  <origin xyz="0.023286 -0.01575 -0.005387" rpy="0 0 0"/>
  <parent link="rim_4_1"/>
  <child link="roller_4_7_1"/>
  <axis xyz="0.584876 -0.0 0.811123"/>
</joint>

<joint name="Revolute 22" type="continuous">
  <origin xyz="0.002072 -0.01575 -0.02381" rpy="0 0 0"/>
  <parent link="rim_4_1"/>
  <child link="roller_4_6_1"/>
  <axis xyz="0.95216 -0.0 -0.305599"/>
</joint>

<joint name="Revolute 23" type="continuous">
  <origin xyz="-0.022005 -0.01575 -0.009328" rpy="0 0 0"/>
  <parent link="rim_4_1"/>
  <child link="roller_4_10_1"/>
  <axis xyz="0.003591 -0.0 -0.999994"/>
</joint>

<joint name="Revolute 24" type="continuous">
  <origin xyz="-0.015672 -0.01575 0.018046" rpy="0 0 0"/>
  <parent link="rim_4_1"/>
  <child link="roller_4_8_1"/>
  <axis xyz="-0.949941 0.0 -0.312431"/>
</joint>

<joint name="Revolute 25" type="continuous">
  <origin xyz="0.00225 -0.009329 -0.022005" rpy="0 0 0"/>
  <parent link="rim_3_1"/>
  <child link="roller_3_10_1"/>
  <axis xyz="0.0 -0.999994 0.003591"/>
</joint>

<joint name="Revolute 26" type="continuous">
  <origin xyz="0.00225 -0.023811 0.002073" rpy="0 0 0"/>
  <parent link="rim_3_1"/>
  <child link="roller_3_6_1"/>
  <axis xyz="0.0 -0.305599 0.95216"/>
</joint>

<joint name="Revolute 27" type="continuous">
  <origin xyz="0.00225 -0.005387 0.023286" rpy="0 0 0"/>
  <parent link="rim_3_1"/>
  <child link="roller_3_7_1"/>
  <axis xyz="-0.0 0.811123 0.584876"/>
</joint>

<joint name="Revolute 28" type="continuous">
  <origin xyz="0.00225 0.020481 0.01232" rpy="0 0 0"/>
  <parent link="rim_3_1"/>
  <child link="roller_3_9_1"/>
  <axis xyz="-0.0 0.806901 -0.590687"/>
</joint>

<joint name="Revolute 29" type="continuous">
  <origin xyz="0.00225 0.018045 -0.015672" rpy="0 0 0"/>
  <parent link="rim_3_1"/>
  <child link="roller_3_8_1"/>
  <axis xyz="0.0 -0.312431 -0.949941"/>
</joint>

<joint name="Revolute 30" type="continuous">
  <origin xyz="0.01575 -0.00917 0.022072" rpy="0 0 0"/>
  <parent link="rim_3_1"/>
  <child link="roller_3_5_1"/>
  <axis xyz="0.0 -0.999994 0.003591"/>
</joint>

<joint name="Revolute 31" type="continuous">
  <origin xyz="0.01575 0.018157 0.015542" rpy="0 0 0"/>
  <parent link="rim_3_1"/>
  <child link="roller_3_1_1"/>
  <axis xyz="0.0 -0.305599 0.95216"/>
</joint>

<joint name="Revolute 32" type="continuous">
  <origin xyz="0.01575 0.020392 -0.012466" rpy="0 0 0"/>
  <parent link="rim_3_1"/>
  <child link="roller_3_2_1"/>
  <axis xyz="-0.0 0.811123 0.584876"/>
</joint>

<joint name="Revolute 33" type="continuous">
  <origin xyz="0.01575 -0.005554 -0.023246" rpy="0 0 0"/>
  <parent link="rim_3_1"/>
  <child link="roller_3_4_1"/>
  <axis xyz="-0.0 0.806901 -0.590687"/>
</joint>

<joint name="Revolute 34" type="continuous">
  <origin xyz="0.01575 -0.023825 -0.001901" rpy="0 0 0"/>
  <parent link="rim_3_1"/>
  <child link="roller_3_3_1"/>
  <axis xyz="0.0 -0.312431 -0.949941"/>
</joint>

<joint name="Revolute 35" type="continuous">
  <origin xyz="0.002072 0.00225 -0.02381" rpy="0 0 0"/>
  <parent link="rim_2_1"/>
  <child link="roller_2_6_1"/>
  <axis xyz="0.95216 -0.0 -0.305599"/>
</joint>

<joint name="Revolute 36" type="continuous">
  <origin xyz="0.023286 0.00225 -0.005387" rpy="0 0 0"/>
  <parent link="rim_2_1"/>
  <child link="roller_2_7_1"/>
  <axis xyz="0.584876 -0.0 0.811123"/>
</joint>

<joint name="Revolute 37" type="continuous">
  <origin xyz="0.012319 0.00225 0.020482" rpy="0 0 0"/>
  <parent link="rim_2_1"/>
  <child link="roller_2_9_1"/>
  <axis xyz="-0.590687 0.0 0.806901"/>
</joint>

<joint name="Revolute 38" type="continuous">
  <origin xyz="-0.015672 0.00225 0.018046" rpy="0 0 0"/>
  <parent link="rim_2_1"/>
  <child link="roller_2_8_1"/>
  <axis xyz="-0.949941 0.0 -0.312431"/>
</joint>

<joint name="Revolute 39" type="continuous">
  <origin xyz="-0.022005 0.00225 -0.009328" rpy="0 0 0"/>
  <parent link="rim_2_1"/>
  <child link="roller_2_10_1"/>
  <axis xyz="0.003591 -0.0 -0.999994"/>
</joint>

<joint name="Revolute 40" type="continuous">
  <origin xyz="0.015542 0.01575 0.018158" rpy="0 0 0"/>
  <parent link="rim_2_1"/>
  <child link="roller_2_1_1"/>
  <axis xyz="0.95216 -0.0 -0.305599"/>
</joint>

<joint name="Revolute 41" type="continuous">
  <origin xyz="-0.012466 0.01575 0.020393" rpy="0 0 0"/>
  <parent link="rim_2_1"/>
  <child link="roller_2_2_1"/>
  <axis xyz="0.584876 -0.0 0.811123"/>
</joint>

<joint name="Revolute 42" type="continuous">
  <origin xyz="-0.023247 0.01575 -0.005554" rpy="0 0 0"/>
  <parent link="rim_2_1"/>
  <child link="roller_2_4_1"/>
  <axis xyz="-0.590687 0.0 0.806901"/>
</joint>

<joint name="Revolute 43" type="continuous">
  <origin xyz="-0.001901 0.01575 -0.023825" rpy="0 0 0"/>
  <parent link="rim_2_1"/>
  <child link="roller_2_3_1"/>
  <axis xyz="-0.949941 0.0 -0.312431"/>
</joint>

<joint name="Revolute 44" type="continuous">
  <origin xyz="0.022071 0.01575 -0.00917" rpy="0 0 0"/>
  <parent link="rim_2_1"/>
  <child link="roller_2_5_1"/>
  <axis xyz="0.003591 -0.0 -0.999994"/>
</joint>

<joint name="Rigid 45" type="fixed">
  <origin xyz="0.0 0.0 -0.019871" rpy="0 0 0"/>
  <parent link="base_link"/>
  <child link="lidar_link_1"/>
</joint>

<joint name="Rigid 46" type="fixed">
  <origin xyz="0.064597 0.065 0.015129" rpy="0 0 0"/>
  <parent link="base_link"/>
  <child link="imu_link_1"/>
</joint>

</robot>
